[2020-06-19 09:16:36,711] [basehttp.py:124] [basehttp:log_message] [INFO]- "GET / HTTP/1.1" 200 5942
[2020-06-19 09:16:36,858] [basehttp.py:124] [basehttp:log_message] [INFO]- "GET /verify HTTP/1.1" 200 1736
[2020-06-19 09:16:36,867] [base.py:152] [base:get_response] [WARNING]- Not Found: /favicon.ico
[2020-06-19 09:16:36,867] [basehttp.py:124] [basehttp:log_message] [WARNING]- "GET /favicon.ico HTTP/1.1" 404 6801
[2020-06-19 09:16:48,786] [basehttp.py:124] [basehttp:log_message] [INFO]- "GET /verify?sn=0.8185510553184485 HTTP/1.1" 200 1782
[2020-06-19 09:16:56,214] [basehttp.py:124] [basehttp:log_message] [INFO]- "POST /dologin HTTP/1.1" 302 0
[2020-06-19 09:16:56,268] [basehttp.py:124] [basehttp:log_message] [INFO]- "GET /web/center HTTP/1.1" 200 6867
[2020-06-19 09:17:04,194] [basehttp.py:124] [basehttp:log_message] [INFO]- "GET /web/index/0 HTTP/1.1" 200 16442
[2020-06-19 09:17:04,208] [basehttp.py:124] [basehttp:log_message] [INFO]- "GET /static/monit/js/js.js HTTP/1.1" 304 0
[2020-06-19 09:17:04,215] [basehttp.py:124] [basehttp:log_message] [INFO]- "GET /static/monit/css/comon0.css HTTP/1.1" 200 11427
[2020-06-19 09:17:04,360] [basehttp.py:124] [basehttp:log_message] [INFO]- "GET /web/visitport HTTP/1.1" 200 229
[2020-06-19 09:17:04,376] [basehttp.py:124] [basehttp:log_message] [INFO]- "GET /web/getnum HTTP/1.1" 200 296
[2020-06-19 09:17:06,168] [basehttp.py:124] [basehttp:log_message] [INFO]- "GET /web/fraction HTTP/1.1" 200 262
[2020-06-19 09:17:06,175] [basehttp.py:124] [basehttp:log_message] [INFO]- "GET /web/rstraffic HTTP/1.1" 200 2564
[2020-06-19 09:17:06,316] [basehttp.py:124] [basehttp:log_message] [INFO]- "GET /web/rqtraffic HTTP/1.1" 200 2914
[2020-06-19 09:17:06,419] [basehttp.py:124] [basehttp:log_message] [INFO]- "GET /web/trend HTTP/1.1" 200 685
[2020-06-19 09:17:08,527] [basehttp.py:124] [basehttp:log_message] [INFO]- "GET /web/domain HTTP/1.1" 200 1276
[2020-06-19 09:17:08,705] [basehttp.py:124] [basehttp:log_message] [INFO]- "GET /web/statuscode HTTP/1.1" 200 5369
[2020-06-19 09:17:17,510] [basehttp.py:124] [basehttp:log_message] [INFO]- "GET /web/Hit HTTP/1.1" 200 37
[2020-06-19 09:17:52,528] [basehttp.py:124] [basehttp:log_message] [INFO]- "GET /web/Source_data HTTP/1.1" 200 590
[2020-06-19 09:18:35,203] [basehttp.py:124] [basehttp:log_message] [INFO]- "GET /web/threaten/indexs?pIndex=0 HTTP/1.1" 200 12225
[2020-06-19 09:18:35,217] [basehttp.py:124] [basehttp:log_message] [INFO]- "GET /static/monit/js/threaten.js HTTP/1.1" 304 0
[2020-06-19 09:18:35,218] [basehttp.py:124] [basehttp:log_message] [INFO]- "GET /static/monit/css/layui.css HTTP/1.1" 304 0
[2020-06-19 09:18:47,528] [basehttp.py:124] [basehttp:log_message] [INFO]- "GET /web/attackmap HTTP/1.1" 200 5
[2020-06-19 09:18:47,542] [basehttp.py:124] [basehttp:log_message] [ERROR]- "GET /web/attackmap HTTP/1.1" 500 59
[2020-06-19 09:18:56,738] [basehttp.py:124] [basehttp:log_message] [INFO]- "GET /web/threaten/thhit HTTP/1.1" 200 771
[2020-06-19 09:18:56,738] [basehttp.py:124] [basehttp:log_message] [INFO]- "GET /web/threaten/thattack HTTP/1.1" 200 512
[2020-06-19 09:18:56,742] [basehttp.py:124] [basehttp:log_message] [INFO]- "GET /web/threaten/threat HTTP/1.1" 200 1002
[2020-06-19 09:18:56,743] [basehttp.py:124] [basehttp:log_message] [INFO]- "GET /web/threaten/thactive HTTP/1.1" 200 282
[2020-06-19 09:18:56,815] [basehttp.py:124] [basehttp:log_message] [INFO]- "GET /web/threaten/indexs?page=1 HTTP/1.1" 200 564
[2020-06-19 09:19:46,488] [basehttp.py:124] [basehttp:log_message] [INFO]- "GET /web/Hit HTTP/1.1" 200 37
[2020-06-19 09:19:59,730] [basehttp.py:124] [basehttp:log_message] [INFO]- "GET /web/threaten/thnews HTTP/1.1" 200 1027
[2020-06-19 09:36:29,277] [threaten.py:330] [threaten:sear_info] [ERROR]- 威胁情报-数据-获取数据出错：'@timestamp'
[2020-06-19 09:36:29,277] [exception.py:135] [exception:handle_uncaught_exception] [ERROR]- Internal Server Error: /web/threaten/indexs
Traceback (most recent call last):
  File "E:\project_env\lib\site-packages\django\core\handlers\exception.py", line 41, in inner
    response = get_response(request)
  File "E:\project_env\lib\site-packages\django\core\handlers\base.py", line 187, in _get_response
    response = self.process_exception_by_middleware(e, request)
  File "E:\project_env\lib\site-packages\django\core\handlers\base.py", line 185, in _get_response
    response = wrapped_callback(request, *callback_args, **callback_kwargs)
  File "E:\project_env\lib\site-packages\django\views\generic\base.py", line 68, in view
    return self.dispatch(request, *args, **kwargs)
  File "E:\project_env\lib\site-packages\django\views\generic\base.py", line 88, in dispatch
    return handler(request, *args, **kwargs)
  File "E:\monitor\HqMonitor\web\views\threaten.py", line 68, in get
    bb = result["aa"]
TypeError: 'bool' object is not subscriptable
[2020-06-19 09:36:29,395] [basehttp.py:124] [basehttp:log_message] [ERROR]- "GET /web/threaten/indexs?pIndex=0 HTTP/1.1" 500 80323
[2020-06-19 09:38:31,532] [threaten.py:330] [threaten:sear_info] [ERROR]- 威胁情报-数据-获取数据出错：'@timestamp'
[2020-06-19 09:38:31,534] [exception.py:135] [exception:handle_uncaught_exception] [ERROR]- Internal Server Error: /web/threaten/indexs
Traceback (most recent call last):
  File "E:\project_env\lib\site-packages\django\core\paginator.py", line 79, in count
    return self.object_list.count()
AttributeError: 'bool' object has no attribute 'count'

During handling of the above exception, another exception occurred:

Traceback (most recent call last):
  File "E:\project_env\lib\site-packages\django\core\handlers\exception.py", line 41, in inner
    response = get_response(request)
  File "E:\project_env\lib\site-packages\django\core\handlers\base.py", line 187, in _get_response
    response = self.process_exception_by_middleware(e, request)
  File "E:\project_env\lib\site-packages\django\core\handlers\base.py", line 185, in _get_response
    response = wrapped_callback(request, *callback_args, **callback_kwargs)
  File "E:\project_env\lib\site-packages\django\views\generic\base.py", line 68, in view
    return self.dispatch(request, *args, **kwargs)
  File "E:\project_env\lib\site-packages\django\views\generic\base.py", line 88, in dispatch
    return handler(request, *args, **kwargs)
  File "E:\monitor\HqMonitor\web\views\threaten.py", line 79, in get
    userlist = paginator.page(1)
  File "E:\project_env\lib\site-packages\django\core\paginator.py", line 57, in page
    number = self.validate_number(number)
  File "E:\project_env\lib\site-packages\django\core\paginator.py", line 46, in validate_number
    if number > self.num_pages:
  File "E:\project_env\lib\site-packages\django\utils\functional.py", line 35, in __get__
    res = instance.__dict__[self.name] = self.func(instance)
  File "E:\project_env\lib\site-packages\django\core\paginator.py", line 91, in num_pages
    if self.count == 0 and not self.allow_empty_first_page:
  File "E:\project_env\lib\site-packages\django\utils\functional.py", line 35, in __get__
    res = instance.__dict__[self.name] = self.func(instance)
  File "E:\project_env\lib\site-packages\django\core\paginator.py", line 84, in count
    return len(self.object_list)
TypeError: object of type 'bool' has no len()
[2020-06-19 09:38:31,658] [basehttp.py:124] [basehttp:log_message] [ERROR]- "GET /web/threaten/indexs?pIndex=0 HTTP/1.1" 500 106990
[2020-06-19 09:38:42,606] [basehttp.py:124] [basehttp:log_message] [INFO]- "GET /web/attackmap HTTP/1.1" 200 4825
[2020-06-19 09:38:42,608] [basehttp.py:124] [basehttp:log_message] [ERROR]- "GET /web/attackmap HTTP/1.1" 500 59
[2020-06-19 09:38:59,344] [threaten.py:330] [threaten:sear_info] [ERROR]- 威胁情报-数据-获取数据出错：'@timestamp'
[2020-06-19 09:38:59,346] [exception.py:135] [exception:handle_uncaught_exception] [ERROR]- Internal Server Error: /web/threaten/indexs
Traceback (most recent call last):
  File "E:\project_env\lib\site-packages\django\core\paginator.py", line 79, in count
    return self.object_list.count()
AttributeError: 'bool' object has no attribute 'count'

During handling of the above exception, another exception occurred:

Traceback (most recent call last):
  File "E:\project_env\lib\site-packages\django\core\handlers\exception.py", line 41, in inner
    response = get_response(request)
  File "E:\project_env\lib\site-packages\django\core\handlers\base.py", line 187, in _get_response
    response = self.process_exception_by_middleware(e, request)
  File "E:\project_env\lib\site-packages\django\core\handlers\base.py", line 185, in _get_response
    response = wrapped_callback(request, *callback_args, **callback_kwargs)
  File "E:\project_env\lib\site-packages\django\views\generic\base.py", line 68, in view
    return self.dispatch(request, *args, **kwargs)
  File "E:\project_env\lib\site-packages\django\views\generic\base.py", line 88, in dispatch
    return handler(request, *args, **kwargs)
  File "E:\monitor\HqMonitor\web\views\threaten.py", line 79, in get
    userlist = paginator.page(1)
  File "E:\project_env\lib\site-packages\django\core\paginator.py", line 57, in page
    number = self.validate_number(number)
  File "E:\project_env\lib\site-packages\django\core\paginator.py", line 46, in validate_number
    if number > self.num_pages:
  File "E:\project_env\lib\site-packages\django\utils\functional.py", line 35, in __get__
    res = instance.__dict__[self.name] = self.func(instance)
  File "E:\project_env\lib\site-packages\django\core\paginator.py", line 91, in num_pages
    if self.count == 0 and not self.allow_empty_first_page:
  File "E:\project_env\lib\site-packages\django\utils\functional.py", line 35, in __get__
    res = instance.__dict__[self.name] = self.func(instance)
  File "E:\project_env\lib\site-packages\django\core\paginator.py", line 84, in count
    return len(self.object_list)
TypeError: object of type 'bool' has no len()
[2020-06-19 09:38:59,373] [basehttp.py:124] [basehttp:log_message] [ERROR]- "GET /web/threaten/indexs?pIndex=0 HTTP/1.1" 500 107125
[2020-06-19 09:41:00,060] [threaten.py:330] [threaten:sear_info] [ERROR]- 威胁情报-数据-获取数据出错：'@timestamp'
[2020-06-19 09:41:00,061] [exception.py:135] [exception:handle_uncaught_exception] [ERROR]- Internal Server Error: /web/threaten/indexs
Traceback (most recent call last):
  File "E:\project_env\lib\site-packages\django\core\handlers\exception.py", line 41, in inner
    response = get_response(request)
  File "E:\project_env\lib\site-packages\django\core\handlers\base.py", line 187, in _get_response
    response = self.process_exception_by_middleware(e, request)
  File "E:\project_env\lib\site-packages\django\core\handlers\base.py", line 185, in _get_response
    response = wrapped_callback(request, *callback_args, **callback_kwargs)
  File "E:\project_env\lib\site-packages\django\views\generic\base.py", line 68, in view
    return self.dispatch(request, *args, **kwargs)
  File "E:\project_env\lib\site-packages\django\views\generic\base.py", line 88, in dispatch
    return handler(request, *args, **kwargs)
  File "E:\monitor\HqMonitor\web\views\threaten.py", line 68, in get
    bb = result["aa"]
TypeError: 'bool' object is not subscriptable
[2020-06-19 09:41:00,165] [basehttp.py:124] [basehttp:log_message] [ERROR]- "GET /web/threaten/indexs?pIndex=0 HTTP/1.1" 500 80323
[2020-06-19 09:41:56,460] [threaten.py:330] [threaten:sear_info] [ERROR]- 威胁情报-数据-获取数据出错：'@timestamp'
[2020-06-19 09:41:56,463] [exception.py:135] [exception:handle_uncaught_exception] [ERROR]- Internal Server Error: /web/threaten/indexs
Traceback (most recent call last):
  File "E:\project_env\lib\site-packages\django\core\paginator.py", line 79, in count
    return self.object_list.count()
AttributeError: 'bool' object has no attribute 'count'

During handling of the above exception, another exception occurred:

Traceback (most recent call last):
  File "E:\project_env\lib\site-packages\django\core\handlers\exception.py", line 41, in inner
    response = get_response(request)
  File "E:\project_env\lib\site-packages\django\core\handlers\base.py", line 187, in _get_response
    response = self.process_exception_by_middleware(e, request)
  File "E:\project_env\lib\site-packages\django\core\handlers\base.py", line 185, in _get_response
    response = wrapped_callback(request, *callback_args, **callback_kwargs)
  File "E:\project_env\lib\site-packages\django\views\generic\base.py", line 68, in view
    return self.dispatch(request, *args, **kwargs)
  File "E:\project_env\lib\site-packages\django\views\generic\base.py", line 88, in dispatch
    return handler(request, *args, **kwargs)
  File "E:\monitor\HqMonitor\web\views\threaten.py", line 79, in get
    userlist = paginator.page(1)
  File "E:\project_env\lib\site-packages\django\core\paginator.py", line 57, in page
    number = self.validate_number(number)
  File "E:\project_env\lib\site-packages\django\core\paginator.py", line 46, in validate_number
    if number > self.num_pages:
  File "E:\project_env\lib\site-packages\django\utils\functional.py", line 35, in __get__
    res = instance.__dict__[self.name] = self.func(instance)
  File "E:\project_env\lib\site-packages\django\core\paginator.py", line 91, in num_pages
    if self.count == 0 and not self.allow_empty_first_page:
  File "E:\project_env\lib\site-packages\django\utils\functional.py", line 35, in __get__
    res = instance.__dict__[self.name] = self.func(instance)
  File "E:\project_env\lib\site-packages\django\core\paginator.py", line 84, in count
    return len(self.object_list)
TypeError: object of type 'bool' has no len()
[2020-06-19 09:41:56,566] [basehttp.py:124] [basehttp:log_message] [ERROR]- "GET /web/threaten/indexs?pIndex=0 HTTP/1.1" 500 107125
[2020-06-19 09:43:47,703] [threaten.py:330] [threaten:sear_info] [ERROR]- 威胁情报-数据-获取数据出错：'geo'
[2020-06-19 09:43:47,705] [exception.py:135] [exception:handle_uncaught_exception] [ERROR]- Internal Server Error: /web/threaten/indexs
Traceback (most recent call last):
  File "E:\project_env\lib\site-packages\django\core\paginator.py", line 79, in count
    return self.object_list.count()
AttributeError: 'bool' object has no attribute 'count'

During handling of the above exception, another exception occurred:

Traceback (most recent call last):
  File "E:\project_env\lib\site-packages\django\core\handlers\exception.py", line 41, in inner
    response = get_response(request)
  File "E:\project_env\lib\site-packages\django\core\handlers\base.py", line 187, in _get_response
    response = self.process_exception_by_middleware(e, request)
  File "E:\project_env\lib\site-packages\django\core\handlers\base.py", line 185, in _get_response
    response = wrapped_callback(request, *callback_args, **callback_kwargs)
  File "E:\project_env\lib\site-packages\django\views\generic\base.py", line 68, in view
    return self.dispatch(request, *args, **kwargs)
  File "E:\project_env\lib\site-packages\django\views\generic\base.py", line 88, in dispatch
    return handler(request, *args, **kwargs)
  File "E:\monitor\HqMonitor\web\views\threaten.py", line 79, in get
    userlist = paginator.page(1)
  File "E:\project_env\lib\site-packages\django\core\paginator.py", line 57, in page
    number = self.validate_number(number)
  File "E:\project_env\lib\site-packages\django\core\paginator.py", line 46, in validate_number
    if number > self.num_pages:
  File "E:\project_env\lib\site-packages\django\utils\functional.py", line 35, in __get__
    res = instance.__dict__[self.name] = self.func(instance)
  File "E:\project_env\lib\site-packages\django\core\paginator.py", line 91, in num_pages
    if self.count == 0 and not self.allow_empty_first_page:
  File "E:\project_env\lib\site-packages\django\utils\functional.py", line 35, in __get__
    res = instance.__dict__[self.name] = self.func(instance)
  File "E:\project_env\lib\site-packages\django\core\paginator.py", line 84, in count
    return len(self.object_list)
TypeError: object of type 'bool' has no len()
[2020-06-19 09:43:47,810] [basehttp.py:124] [basehttp:log_message] [ERROR]- "GET /web/threaten/indexs?pIndex=0 HTTP/1.1" 500 107125
[2020-06-19 09:44:50,564] [threaten.py:331] [threaten:sear_info] [ERROR]- 威胁情报-数据-获取数据出错：'geo'
[2020-06-19 09:44:50,566] [exception.py:135] [exception:handle_uncaught_exception] [ERROR]- Internal Server Error: /web/threaten/indexs
Traceback (most recent call last):
  File "E:\project_env\lib\site-packages\django\core\paginator.py", line 79, in count
    return self.object_list.count()
AttributeError: 'bool' object has no attribute 'count'

During handling of the above exception, another exception occurred:

Traceback (most recent call last):
  File "E:\project_env\lib\site-packages\django\core\handlers\exception.py", line 41, in inner
    response = get_response(request)
  File "E:\project_env\lib\site-packages\django\core\handlers\base.py", line 187, in _get_response
    response = self.process_exception_by_middleware(e, request)
  File "E:\project_env\lib\site-packages\django\core\handlers\base.py", line 185, in _get_response
    response = wrapped_callback(request, *callback_args, **callback_kwargs)
  File "E:\project_env\lib\site-packages\django\views\generic\base.py", line 68, in view
    return self.dispatch(request, *args, **kwargs)
  File "E:\project_env\lib\site-packages\django\views\generic\base.py", line 88, in dispatch
    return handler(request, *args, **kwargs)
  File "E:\monitor\HqMonitor\web\views\threaten.py", line 79, in get
    userlist = paginator.page(1)
  File "E:\project_env\lib\site-packages\django\core\paginator.py", line 57, in page
    number = self.validate_number(number)
  File "E:\project_env\lib\site-packages\django\core\paginator.py", line 46, in validate_number
    if number > self.num_pages:
  File "E:\project_env\lib\site-packages\django\utils\functional.py", line 35, in __get__
    res = instance.__dict__[self.name] = self.func(instance)
  File "E:\project_env\lib\site-packages\django\core\paginator.py", line 91, in num_pages
    if self.count == 0 and not self.allow_empty_first_page:
  File "E:\project_env\lib\site-packages\django\utils\functional.py", line 35, in __get__
    res = instance.__dict__[self.name] = self.func(instance)
  File "E:\project_env\lib\site-packages\django\core\paginator.py", line 84, in count
    return len(self.object_list)
TypeError: object of type 'bool' has no len()
[2020-06-19 09:44:50,668] [basehttp.py:124] [basehttp:log_message] [ERROR]- "GET /web/threaten/indexs?pIndex=0 HTTP/1.1" 500 107125
[2020-06-19 09:47:51,804] [threaten.py:333] [threaten:sear_info] [ERROR]- 威胁情报-数据-获取数据出错：'geo'
[2020-06-19 09:47:51,806] [exception.py:135] [exception:handle_uncaught_exception] [ERROR]- Internal Server Error: /web/threaten/indexs
Traceback (most recent call last):
  File "E:\project_env\lib\site-packages\django\core\paginator.py", line 79, in count
    return self.object_list.count()
AttributeError: 'bool' object has no attribute 'count'

During handling of the above exception, another exception occurred:

Traceback (most recent call last):
  File "E:\project_env\lib\site-packages\django\core\handlers\exception.py", line 41, in inner
    response = get_response(request)
  File "E:\project_env\lib\site-packages\django\core\handlers\base.py", line 187, in _get_response
    response = self.process_exception_by_middleware(e, request)
  File "E:\project_env\lib\site-packages\django\core\handlers\base.py", line 185, in _get_response
    response = wrapped_callback(request, *callback_args, **callback_kwargs)
  File "E:\project_env\lib\site-packages\django\views\generic\base.py", line 68, in view
    return self.dispatch(request, *args, **kwargs)
  File "E:\project_env\lib\site-packages\django\views\generic\base.py", line 88, in dispatch
    return handler(request, *args, **kwargs)
  File "E:\monitor\HqMonitor\web\views\threaten.py", line 79, in get
    userlist = paginator.page(1)
  File "E:\project_env\lib\site-packages\django\core\paginator.py", line 57, in page
    number = self.validate_number(number)
  File "E:\project_env\lib\site-packages\django\core\paginator.py", line 46, in validate_number
    if number > self.num_pages:
  File "E:\project_env\lib\site-packages\django\utils\functional.py", line 35, in __get__
    res = instance.__dict__[self.name] = self.func(instance)
  File "E:\project_env\lib\site-packages\django\core\paginator.py", line 91, in num_pages
    if self.count == 0 and not self.allow_empty_first_page:
  File "E:\project_env\lib\site-packages\django\utils\functional.py", line 35, in __get__
    res = instance.__dict__[self.name] = self.func(instance)
  File "E:\project_env\lib\site-packages\django\core\paginator.py", line 84, in count
    return len(self.object_list)
TypeError: object of type 'bool' has no len()
[2020-06-19 09:47:51,911] [basehttp.py:124] [basehttp:log_message] [ERROR]- "GET /web/threaten/indexs?pIndex=0 HTTP/1.1" 500 107125
[2020-06-19 09:57:27,311] [threaten.py:317] [threaten:sear_info] [ERROR]- 解析威胁情报详细数据报错：'geo'
[2020-06-19 09:57:27,311] [threaten.py:317] [threaten:sear_info] [ERROR]- 解析威胁情报详细数据报错：'geo'
[2020-06-19 09:57:27,312] [threaten.py:317] [threaten:sear_info] [ERROR]- 解析威胁情报详细数据报错：'geo'
[2020-06-19 09:57:27,313] [exception.py:135] [exception:handle_uncaught_exception] [ERROR]- Internal Server Error: /web/threaten/indexs
Traceback (most recent call last):
  File "E:\project_env\lib\site-packages\django\core\handlers\exception.py", line 41, in inner
    response = get_response(request)
  File "E:\project_env\lib\site-packages\django\core\handlers\base.py", line 187, in _get_response
    response = self.process_exception_by_middleware(e, request)
  File "E:\project_env\lib\site-packages\django\core\handlers\base.py", line 185, in _get_response
    response = wrapped_callback(request, *callback_args, **callback_kwargs)
  File "E:\project_env\lib\site-packages\django\views\generic\base.py", line 68, in view
    return self.dispatch(request, *args, **kwargs)
  File "E:\project_env\lib\site-packages\django\views\generic\base.py", line 88, in dispatch
    return handler(request, *args, **kwargs)
  File "E:\monitor\HqMonitor\web\views\threaten.py", line 68, in get
    bb = result["aa"]
TypeError: string indices must be integers
[2020-06-19 09:57:27,408] [basehttp.py:124] [basehttp:log_message] [ERROR]- "GET /web/threaten/indexs?pIndex=0 HTTP/1.1" 500 81236
[2020-06-19 10:00:23,071] [threaten.py:317] [threaten:sear_info] [ERROR]- 解析威胁情报详细数据报错：'geo'
[2020-06-19 10:00:23,071] [threaten.py:317] [threaten:sear_info] [ERROR]- 解析威胁情报详细数据报错：'geo'
[2020-06-19 10:00:23,071] [threaten.py:317] [threaten:sear_info] [ERROR]- 解析威胁情报详细数据报错：'geo'
[2020-06-19 10:00:23,089] [basehttp.py:124] [basehttp:log_message] [INFO]- "GET /web/threaten/indexs?pIndex=0 HTTP/1.1" 200 12225
[2020-06-19 10:00:25,464] [basehttp.py:124] [basehttp:log_message] [INFO]- "GET /web/threaten/thactive HTTP/1.1" 200 281
[2020-06-19 10:00:25,469] [basehttp.py:124] [basehttp:log_message] [INFO]- "GET /web/threaten/thattack HTTP/1.1" 200 564
[2020-06-19 10:00:25,486] [basehttp.py:124] [basehttp:log_message] [INFO]- "GET /web/threaten/thhit HTTP/1.1" 200 757
[2020-06-19 10:00:27,729] [basehttp.py:124] [basehttp:log_message] [INFO]- "GET /web/threaten/threat HTTP/1.1" 200 1000
[2020-06-19 10:00:27,745] [basehttp.py:124] [basehttp:log_message] [INFO]- "GET /web/threaten/thnews HTTP/1.1" 200 1025
[2020-06-19 10:00:27,760] [threaten.py:317] [threaten:sear_info] [ERROR]- 解析威胁情报详细数据报错：'geo'
[2020-06-19 10:00:27,760] [threaten.py:317] [threaten:sear_info] [ERROR]- 解析威胁情报详细数据报错：'geo'
[2020-06-19 10:00:27,762] [threaten.py:317] [threaten:sear_info] [ERROR]- 解析威胁情报详细数据报错：'geo'
[2020-06-19 10:00:27,763] [basehttp.py:124] [basehttp:log_message] [INFO]- "GET /web/threaten/indexs?page=1 HTTP/1.1" 200 564
[2020-06-19 10:00:27,764] [basehttp.py:124] [basehttp:log_message] [INFO]- "GET /web/Hit HTTP/1.1" 200 37
[2020-06-19 10:00:58,114] [threaten.py:317] [threaten:sear_info] [ERROR]- 解析威胁情报详细数据报错：'geo'
[2020-06-19 10:00:58,114] [threaten.py:317] [threaten:sear_info] [ERROR]- 解析威胁情报详细数据报错：'geo'
[2020-06-19 10:00:58,114] [threaten.py:317] [threaten:sear_info] [ERROR]- 解析威胁情报详细数据报错：'geo'
[2020-06-19 10:00:58,132] [basehttp.py:124] [basehttp:log_message] [INFO]- "GET /web/threaten/indexs?pIndex=0 HTTP/1.1" 200 13173
[2020-06-19 10:00:59,644] [threaten.py:317] [threaten:sear_info] [ERROR]- 解析威胁情报详细数据报错：'geo'
[2020-06-19 10:00:59,644] [threaten.py:317] [threaten:sear_info] [ERROR]- 解析威胁情报详细数据报错：'geo'
[2020-06-19 10:00:59,645] [threaten.py:317] [threaten:sear_info] [ERROR]- 解析威胁情报详细数据报错：'geo'
[2020-06-19 10:00:59,647] [basehttp.py:124] [basehttp:log_message] [INFO]- "GET /web/threaten/indexs?page=1 HTTP/1.1" 200 1526
[2020-06-19 10:00:59,662] [basehttp.py:124] [basehttp:log_message] [INFO]- "GET /web/threaten/thattack HTTP/1.1" 200 564
[2020-06-19 10:00:59,675] [basehttp.py:124] [basehttp:log_message] [INFO]- "GET /web/threaten/thhit HTTP/1.1" 200 757
[2020-06-19 10:00:59,679] [basehttp.py:124] [basehttp:log_message] [INFO]- "GET /web/threaten/thactive HTTP/1.1" 200 281
[2020-06-19 10:00:59,694] [basehttp.py:124] [basehttp:log_message] [INFO]- "GET /web/threaten/threat HTTP/1.1" 200 1000
[2020-06-19 10:00:59,701] [basehttp.py:124] [basehttp:log_message] [INFO]- "GET /web/threaten/thnews HTTP/1.1" 200 1025
[2020-06-19 10:01:03,711] [basehttp.py:124] [basehttp:log_message] [INFO]- "GET /web/attackmap HTTP/1.1" 200 4248
[2020-06-19 10:01:03,713] [basehttp.py:124] [basehttp:log_message] [ERROR]- "GET /web/attackmap HTTP/1.1" 500 59
[2020-06-19 10:01:10,962] [basehttp.py:124] [basehttp:log_message] [INFO]- "GET /web/Hit HTTP/1.1" 200 37
[2020-06-19 10:01:11,003] [threaten.py:317] [threaten:sear_info] [ERROR]- 解析威胁情报详细数据报错：'geo'
[2020-06-19 10:01:11,003] [threaten.py:317] [threaten:sear_info] [ERROR]- 解析威胁情报详细数据报错：'geo'
[2020-06-19 10:01:11,004] [threaten.py:317] [threaten:sear_info] [ERROR]- 解析威胁情报详细数据报错：'geo'
[2020-06-19 10:01:11,004] [threaten.py:317] [threaten:sear_info] [ERROR]- 解析威胁情报详细数据报错：'geo'
[2020-06-19 10:01:11,005] [threaten.py:317] [threaten:sear_info] [ERROR]- 解析威胁情报详细数据报错：'geo'
[2020-06-19 10:01:11,005] [threaten.py:317] [threaten:sear_info] [ERROR]- 解析威胁情报详细数据报错：'geo'
[2020-06-19 10:01:11,006] [threaten.py:317] [threaten:sear_info] [ERROR]- 解析威胁情报详细数据报错：'geo'
[2020-06-19 10:01:11,007] [threaten.py:317] [threaten:sear_info] [ERROR]- 解析威胁情报详细数据报错：'geo'
[2020-06-19 10:01:11,007] [threaten.py:317] [threaten:sear_info] [ERROR]- 解析威胁情报详细数据报错：'geo'
[2020-06-19 10:01:11,009] [basehttp.py:124] [basehttp:log_message] [INFO]- "GET /web/threaten/indexs?page=4 HTTP/1.1" 200 1516
[2020-06-19 10:01:11,009] [threaten.py:317] [threaten:sear_info] [ERROR]- 解析威胁情报详细数据报错：'geo'
[2020-06-19 10:01:11,010] [threaten.py:317] [threaten:sear_info] [ERROR]- 解析威胁情报详细数据报错：'geo'
[2020-06-19 10:01:11,010] [threaten.py:317] [threaten:sear_info] [ERROR]- 解析威胁情报详细数据报错：'geo'
[2020-06-19 10:01:11,011] [basehttp.py:124] [basehttp:log_message] [INFO]- "GET /web/threaten/indexs?page=5 HTTP/1.1" 200 1118
[2020-06-19 10:01:11,013] [basehttp.py:124] [basehttp:log_message] [INFO]- "GET /web/threaten/indexs?page=1 HTTP/1.1" 200 1515
[2020-06-19 10:01:11,014] [basehttp.py:124] [basehttp:log_message] [INFO]- "GET /web/threaten/indexs?page=3 HTTP/1.1" 200 1440
[2020-06-19 10:01:11,018] [threaten.py:317] [threaten:sear_info] [ERROR]- 解析威胁情报详细数据报错：'geo'
[2020-06-19 10:01:11,018] [threaten.py:317] [threaten:sear_info] [ERROR]- 解析威胁情报详细数据报错：'geo'
[2020-06-19 10:01:11,019] [threaten.py:317] [threaten:sear_info] [ERROR]- 解析威胁情报详细数据报错：'geo'
[2020-06-19 10:01:11,021] [basehttp.py:124] [basehttp:log_message] [INFO]- "GET /web/threaten/indexs?page=2 HTTP/1.1" 200 1516
[2020-06-19 10:02:40,735] [threaten.py:317] [threaten:sear_info] [ERROR]- 解析威胁情报详细数据报错：'geo'
[2020-06-19 10:02:40,735] [threaten.py:317] [threaten:sear_info] [ERROR]- 解析威胁情报详细数据报错：'geo'
[2020-06-19 10:02:40,735] [threaten.py:317] [threaten:sear_info] [ERROR]- 解析威胁情报详细数据报错：'geo'
[2020-06-19 10:02:40,735] [threaten.py:317] [threaten:sear_info] [ERROR]- 解析威胁情报详细数据报错：'geo'
[2020-06-19 10:02:40,736] [threaten.py:317] [threaten:sear_info] [ERROR]- 解析威胁情报详细数据报错：'geo'
[2020-06-19 10:02:40,736] [threaten.py:317] [threaten:sear_info] [ERROR]- 解析威胁情报详细数据报错：'geo'
[2020-06-19 10:02:40,736] [threaten.py:317] [threaten:sear_info] [ERROR]- 解析威胁情报详细数据报错：'geo'
[2020-06-19 10:02:40,736] [threaten.py:317] [threaten:sear_info] [ERROR]- 解析威胁情报详细数据报错：'geo'
[2020-06-19 10:02:40,737] [threaten.py:317] [threaten:sear_info] [ERROR]- 解析威胁情报详细数据报错：'geo'
[2020-06-19 10:02:40,737] [threaten.py:317] [threaten:sear_info] [ERROR]- 解析威胁情报详细数据报错：'geo'
[2020-06-19 10:02:40,737] [threaten.py:317] [threaten:sear_info] [ERROR]- 解析威胁情报详细数据报错：'geo'
[2020-06-19 10:02:40,737] [threaten.py:317] [threaten:sear_info] [ERROR]- 解析威胁情报详细数据报错：'geo'
[2020-06-19 10:02:40,738] [threaten.py:317] [threaten:sear_info] [ERROR]- 解析威胁情报详细数据报错：'geo'
[2020-06-19 10:02:40,743] [basehttp.py:124] [basehttp:log_message] [INFO]- "GET /web/threaten/indexs?pIndex=0 HTTP/1.1" 200 12878
[2020-06-19 10:02:42,065] [basehttp.py:124] [basehttp:log_message] [INFO]- "GET /web/threaten/thattack HTTP/1.1" 200 564
[2020-06-19 10:02:42,075] [threaten.py:317] [threaten:sear_info] [ERROR]- 解析威胁情报详细数据报错：'geo'
[2020-06-19 10:02:42,075] [threaten.py:317] [threaten:sear_info] [ERROR]- 解析威胁情报详细数据报错：'geo'
[2020-06-19 10:02:42,075] [threaten.py:317] [threaten:sear_info] [ERROR]- 解析威胁情报详细数据报错：'geo'
[2020-06-19 10:02:42,075] [threaten.py:317] [threaten:sear_info] [ERROR]- 解析威胁情报详细数据报错：'geo'
[2020-06-19 10:02:42,076] [threaten.py:317] [threaten:sear_info] [ERROR]- 解析威胁情报详细数据报错：'geo'
[2020-06-19 10:02:42,076] [threaten.py:317] [threaten:sear_info] [ERROR]- 解析威胁情报详细数据报错：'geo'
[2020-06-19 10:02:42,076] [threaten.py:317] [threaten:sear_info] [ERROR]- 解析威胁情报详细数据报错：'geo'
[2020-06-19 10:02:42,076] [threaten.py:317] [threaten:sear_info] [ERROR]- 解析威胁情报详细数据报错：'geo'
[2020-06-19 10:02:42,077] [threaten.py:317] [threaten:sear_info] [ERROR]- 解析威胁情报详细数据报错：'geo'
[2020-06-19 10:02:42,077] [threaten.py:317] [threaten:sear_info] [ERROR]- 解析威胁情报详细数据报错：'geo'
[2020-06-19 10:02:42,077] [threaten.py:317] [threaten:sear_info] [ERROR]- 解析威胁情报详细数据报错：'geo'
[2020-06-19 10:02:42,077] [threaten.py:317] [threaten:sear_info] [ERROR]- 解析威胁情报详细数据报错：'geo'
[2020-06-19 10:02:42,078] [threaten.py:317] [threaten:sear_info] [ERROR]- 解析威胁情报详细数据报错：'geo'
[2020-06-19 10:02:42,079] [basehttp.py:124] [basehttp:log_message] [INFO]- "GET /web/threaten/indexs?page=1 HTTP/1.1" 200 1530
[2020-06-19 10:02:42,080] [basehttp.py:124] [basehttp:log_message] [INFO]- "GET /web/threaten/thhit HTTP/1.1" 200 770
[2020-06-19 10:02:42,086] [basehttp.py:124] [basehttp:log_message] [INFO]- "GET /web/threaten/thactive HTTP/1.1" 200 281
[2020-06-19 10:02:42,086] [basehttp.py:124] [basehttp:log_message] [INFO]- "GET /web/threaten/threat HTTP/1.1" 200 1000
[2020-06-19 10:02:53,363] [basehttp.py:124] [basehttp:log_message] [INFO]- "GET /web/Hit HTTP/1.1" 200 37
[2020-06-19 10:02:53,406] [basehttp.py:124] [basehttp:log_message] [INFO]- "GET /web/threaten/thnews HTTP/1.1" 200 1025
[2020-06-19 10:04:57,921] [threaten.py:317] [threaten:sear_info] [ERROR]- 解析威胁情报详细数据报错：'geo'
[2020-06-19 10:04:57,921] [threaten.py:317] [threaten:sear_info] [ERROR]- 解析威胁情报详细数据报错：'geo'
[2020-06-19 10:04:57,921] [threaten.py:317] [threaten:sear_info] [ERROR]- 解析威胁情报详细数据报错：'geo'
[2020-06-19 10:04:57,921] [threaten.py:317] [threaten:sear_info] [ERROR]- 解析威胁情报详细数据报错：'geo'
[2020-06-19 10:04:57,922] [threaten.py:317] [threaten:sear_info] [ERROR]- 解析威胁情报详细数据报错：'geo'
[2020-06-19 10:04:57,922] [threaten.py:317] [threaten:sear_info] [ERROR]- 解析威胁情报详细数据报错：'geo'
[2020-06-19 10:04:57,922] [threaten.py:317] [threaten:sear_info] [ERROR]- 解析威胁情报详细数据报错：'geo'
[2020-06-19 10:04:57,922] [threaten.py:317] [threaten:sear_info] [ERROR]- 解析威胁情报详细数据报错：'geo'
[2020-06-19 10:04:57,923] [threaten.py:317] [threaten:sear_info] [ERROR]- 解析威胁情报详细数据报错：'geo'
[2020-06-19 10:04:57,923] [threaten.py:317] [threaten:sear_info] [ERROR]- 解析威胁情报详细数据报错：'geo'
[2020-06-19 10:04:57,923] [threaten.py:317] [threaten:sear_info] [ERROR]- 解析威胁情报详细数据报错：'geo'
[2020-06-19 10:04:57,923] [threaten.py:317] [threaten:sear_info] [ERROR]- 解析威胁情报详细数据报错：'geo'
[2020-06-19 10:04:57,924] [threaten.py:317] [threaten:sear_info] [ERROR]- 解析威胁情报详细数据报错：'geo'
[2020-06-19 10:04:57,924] [threaten.py:317] [threaten:sear_info] [ERROR]- 解析威胁情报详细数据报错：'geo'
[2020-06-19 10:04:57,924] [threaten.py:317] [threaten:sear_info] [ERROR]- 解析威胁情报详细数据报错：'geo'
[2020-06-19 10:04:57,924] [threaten.py:317] [threaten:sear_info] [ERROR]- 解析威胁情报详细数据报错：'geo'
[2020-06-19 10:04:57,924] [threaten.py:317] [threaten:sear_info] [ERROR]- 解析威胁情报详细数据报错：'geo'
[2020-06-19 10:04:57,925] [threaten.py:317] [threaten:sear_info] [ERROR]- 解析威胁情报详细数据报错：'geo'
[2020-06-19 10:04:57,925] [threaten.py:317] [threaten:sear_info] [ERROR]- 解析威胁情报详细数据报错：'geo'
[2020-06-19 10:04:57,925] [threaten.py:317] [threaten:sear_info] [ERROR]- 解析威胁情报详细数据报错：'geo'
[2020-06-19 10:04:57,925] [threaten.py:317] [threaten:sear_info] [ERROR]- 解析威胁情报详细数据报错：'geo'
[2020-06-19 10:04:57,925] [threaten.py:317] [threaten:sear_info] [ERROR]- 解析威胁情报详细数据报错：'geo'
[2020-06-19 10:04:57,927] [basehttp.py:124] [basehttp:log_message] [INFO]- "GET /web/threaten/indexs?page=2 HTTP/1.1" 200 1537
[2020-06-19 10:04:59,099] [threaten.py:317] [threaten:sear_info] [ERROR]- 解析威胁情报详细数据报错：'geo'
[2020-06-19 10:04:59,125] [threaten.py:317] [threaten:sear_info] [ERROR]- 解析威胁情报详细数据报错：'geo'
[2020-06-19 10:04:59,192] [threaten.py:317] [threaten:sear_info] [ERROR]- 解析威胁情报详细数据报错：'geo'
[2020-06-19 10:04:59,192] [threaten.py:317] [threaten:sear_info] [ERROR]- 解析威胁情报详细数据报错：'geo'
[2020-06-19 10:04:59,192] [threaten.py:317] [threaten:sear_info] [ERROR]- 解析威胁情报详细数据报错：'geo'
[2020-06-19 10:04:59,192] [threaten.py:317] [threaten:sear_info] [ERROR]- 解析威胁情报详细数据报错：'geo'
[2020-06-19 10:04:59,193] [threaten.py:317] [threaten:sear_info] [ERROR]- 解析威胁情报详细数据报错：'geo'
[2020-06-19 10:04:59,193] [threaten.py:317] [threaten:sear_info] [ERROR]- 解析威胁情报详细数据报错：'geo'
[2020-06-19 10:04:59,193] [threaten.py:317] [threaten:sear_info] [ERROR]- 解析威胁情报详细数据报错：'geo'
[2020-06-19 10:04:59,193] [threaten.py:317] [threaten:sear_info] [ERROR]- 解析威胁情报详细数据报错：'geo'
[2020-06-19 10:04:59,193] [threaten.py:317] [threaten:sear_info] [ERROR]- 解析威胁情报详细数据报错：'geo'
[2020-06-19 10:04:59,193] [threaten.py:317] [threaten:sear_info] [ERROR]- 解析威胁情报详细数据报错：'geo'
[2020-06-19 10:04:59,194] [threaten.py:317] [threaten:sear_info] [ERROR]- 解析威胁情报详细数据报错：'geo'
[2020-06-19 10:04:59,194] [threaten.py:317] [threaten:sear_info] [ERROR]- 解析威胁情报详细数据报错：'geo'
[2020-06-19 10:04:59,194] [threaten.py:317] [threaten:sear_info] [ERROR]- 解析威胁情报详细数据报错：'geo'
[2020-06-19 10:04:59,194] [threaten.py:317] [threaten:sear_info] [ERROR]- 解析威胁情报详细数据报错：'geo'
[2020-06-19 10:04:59,194] [threaten.py:317] [threaten:sear_info] [ERROR]- 解析威胁情报详细数据报错：'geo'
[2020-06-19 10:04:59,195] [threaten.py:317] [threaten:sear_info] [ERROR]- 解析威胁情报详细数据报错：'geo'
[2020-06-19 10:04:59,195] [threaten.py:317] [threaten:sear_info] [ERROR]- 解析威胁情报详细数据报错：'geo'
[2020-06-19 10:04:59,195] [threaten.py:317] [threaten:sear_info] [ERROR]- 解析威胁情报详细数据报错：'geo'
[2020-06-19 10:04:59,195] [threaten.py:317] [threaten:sear_info] [ERROR]- 解析威胁情报详细数据报错：'geo'
[2020-06-19 10:04:59,196] [threaten.py:317] [threaten:sear_info] [ERROR]- 解析威胁情报详细数据报错：'geo'
[2020-06-19 10:04:59,197] [basehttp.py:124] [basehttp:log_message] [INFO]- "GET /web/threaten/indexs?page=3 HTTP/1.1" 200 1216
[2020-06-19 10:05:00,577] [threaten.py:317] [threaten:sear_info] [ERROR]- 解析威胁情报详细数据报错：'geo'
[2020-06-19 10:05:00,578] [threaten.py:317] [threaten:sear_info] [ERROR]- 解析威胁情报详细数据报错：'geo'
[2020-06-19 10:05:00,578] [threaten.py:317] [threaten:sear_info] [ERROR]- 解析威胁情报详细数据报错：'geo'
[2020-06-19 10:05:00,578] [threaten.py:317] [threaten:sear_info] [ERROR]- 解析威胁情报详细数据报错：'geo'
[2020-06-19 10:05:00,578] [threaten.py:317] [threaten:sear_info] [ERROR]- 解析威胁情报详细数据报错：'geo'
[2020-06-19 10:05:00,579] [threaten.py:317] [threaten:sear_info] [ERROR]- 解析威胁情报详细数据报错：'geo'
[2020-06-19 10:05:00,579] [threaten.py:317] [threaten:sear_info] [ERROR]- 解析威胁情报详细数据报错：'geo'
[2020-06-19 10:05:00,579] [threaten.py:317] [threaten:sear_info] [ERROR]- 解析威胁情报详细数据报错：'geo'
[2020-06-19 10:05:00,579] [threaten.py:317] [threaten:sear_info] [ERROR]- 解析威胁情报详细数据报错：'geo'
[2020-06-19 10:05:00,579] [threaten.py:317] [threaten:sear_info] [ERROR]- 解析威胁情报详细数据报错：'geo'
[2020-06-19 10:05:00,580] [threaten.py:317] [threaten:sear_info] [ERROR]- 解析威胁情报详细数据报错：'geo'
[2020-06-19 10:05:00,580] [threaten.py:317] [threaten:sear_info] [ERROR]- 解析威胁情报详细数据报错：'geo'
[2020-06-19 10:05:00,580] [threaten.py:317] [threaten:sear_info] [ERROR]- 解析威胁情报详细数据报错：'geo'
[2020-06-19 10:05:00,580] [threaten.py:317] [threaten:sear_info] [ERROR]- 解析威胁情报详细数据报错：'geo'
[2020-06-19 10:05:00,580] [threaten.py:317] [threaten:sear_info] [ERROR]- 解析威胁情报详细数据报错：'geo'
[2020-06-19 10:05:00,581] [threaten.py:317] [threaten:sear_info] [ERROR]- 解析威胁情报详细数据报错：'geo'
[2020-06-19 10:05:00,582] [basehttp.py:124] [basehttp:log_message] [INFO]- "GET /web/threaten/indexs?page=4 HTTP/1.1" 200 662
[2020-06-19 10:05:02,110] [threaten.py:317] [threaten:sear_info] [ERROR]- 解析威胁情报详细数据报错：'geo'
[2020-06-19 10:05:02,110] [threaten.py:317] [threaten:sear_info] [ERROR]- 解析威胁情报详细数据报错：'geo'
[2020-06-19 10:05:02,110] [threaten.py:317] [threaten:sear_info] [ERROR]- 解析威胁情报详细数据报错：'geo'
[2020-06-19 10:05:02,110] [threaten.py:317] [threaten:sear_info] [ERROR]- 解析威胁情报详细数据报错：'geo'
[2020-06-19 10:05:02,111] [threaten.py:317] [threaten:sear_info] [ERROR]- 解析威胁情报详细数据报错：'geo'
[2020-06-19 10:05:02,111] [threaten.py:317] [threaten:sear_info] [ERROR]- 解析威胁情报详细数据报错：'geo'
[2020-06-19 10:05:02,111] [threaten.py:317] [threaten:sear_info] [ERROR]- 解析威胁情报详细数据报错：'geo'
[2020-06-19 10:05:02,111] [threaten.py:317] [threaten:sear_info] [ERROR]- 解析威胁情报详细数据报错：'geo'
[2020-06-19 10:05:02,112] [threaten.py:317] [threaten:sear_info] [ERROR]- 解析威胁情报详细数据报错：'geo'
[2020-06-19 10:05:02,112] [threaten.py:317] [threaten:sear_info] [ERROR]- 解析威胁情报详细数据报错：'geo'
[2020-06-19 10:05:02,112] [threaten.py:317] [threaten:sear_info] [ERROR]- 解析威胁情报详细数据报错：'geo'
[2020-06-19 10:05:02,112] [threaten.py:317] [threaten:sear_info] [ERROR]- 解析威胁情报详细数据报错：'geo'
[2020-06-19 10:05:02,113] [threaten.py:317] [threaten:sear_info] [ERROR]- 解析威胁情报详细数据报错：'geo'
[2020-06-19 10:05:02,113] [threaten.py:317] [threaten:sear_info] [ERROR]- 解析威胁情报详细数据报错：'geo'
[2020-06-19 10:05:02,113] [threaten.py:317] [threaten:sear_info] [ERROR]- 解析威胁情报详细数据报错：'geo'
[2020-06-19 10:05:02,113] [threaten.py:317] [threaten:sear_info] [ERROR]- 解析威胁情报详细数据报错：'geo'
[2020-06-19 10:05:02,115] [basehttp.py:124] [basehttp:log_message] [INFO]- "GET /web/threaten/indexs?page=3 HTTP/1.1" 200 1515
[2020-06-19 10:05:03,589] [threaten.py:317] [threaten:sear_info] [ERROR]- 解析威胁情报详细数据报错：'geo'
[2020-06-19 10:05:03,590] [threaten.py:317] [threaten:sear_info] [ERROR]- 解析威胁情报详细数据报错：'geo'
[2020-06-19 10:05:03,590] [threaten.py:317] [threaten:sear_info] [ERROR]- 解析威胁情报详细数据报错：'geo'
[2020-06-19 10:05:03,590] [threaten.py:317] [threaten:sear_info] [ERROR]- 解析威胁情报详细数据报错：'geo'
[2020-06-19 10:05:03,590] [threaten.py:317] [threaten:sear_info] [ERROR]- 解析威胁情报详细数据报错：'geo'
[2020-06-19 10:05:03,590] [threaten.py:317] [threaten:sear_info] [ERROR]- 解析威胁情报详细数据报错：'geo'
[2020-06-19 10:05:03,591] [threaten.py:317] [threaten:sear_info] [ERROR]- 解析威胁情报详细数据报错：'geo'
[2020-06-19 10:05:03,591] [threaten.py:317] [threaten:sear_info] [ERROR]- 解析威胁情报详细数据报错：'geo'
[2020-06-19 10:05:03,591] [threaten.py:317] [threaten:sear_info] [ERROR]- 解析威胁情报详细数据报错：'geo'
[2020-06-19 10:05:03,591] [threaten.py:317] [threaten:sear_info] [ERROR]- 解析威胁情报详细数据报错：'geo'
[2020-06-19 10:05:03,591] [threaten.py:317] [threaten:sear_info] [ERROR]- 解析威胁情报详细数据报错：'geo'
[2020-06-19 10:05:03,592] [threaten.py:317] [threaten:sear_info] [ERROR]- 解析威胁情报详细数据报错：'geo'
[2020-06-19 10:05:03,592] [threaten.py:317] [threaten:sear_info] [ERROR]- 解析威胁情报详细数据报错：'geo'
[2020-06-19 10:05:03,592] [threaten.py:317] [threaten:sear_info] [ERROR]- 解析威胁情报详细数据报错：'geo'
[2020-06-19 10:05:03,592] [threaten.py:317] [threaten:sear_info] [ERROR]- 解析威胁情报详细数据报错：'geo'
[2020-06-19 10:05:03,593] [threaten.py:317] [threaten:sear_info] [ERROR]- 解析威胁情报详细数据报错：'geo'
[2020-06-19 10:05:03,595] [basehttp.py:124] [basehttp:log_message] [INFO]- "GET /web/threaten/indexs?page=4 HTTP/1.1" 200 662
[2020-06-19 10:05:12,134] [threaten.py:317] [threaten:sear_info] [ERROR]- 解析威胁情报详细数据报错：'geo'
[2020-06-19 10:05:12,135] [threaten.py:317] [threaten:sear_info] [ERROR]- 解析威胁情报详细数据报错：'geo'
[2020-06-19 10:05:12,135] [threaten.py:317] [threaten:sear_info] [ERROR]- 解析威胁情报详细数据报错：'geo'
[2020-06-19 10:05:12,135] [threaten.py:317] [threaten:sear_info] [ERROR]- 解析威胁情报详细数据报错：'geo'
[2020-06-19 10:05:12,135] [threaten.py:317] [threaten:sear_info] [ERROR]- 解析威胁情报详细数据报错：'geo'
[2020-06-19 10:05:12,135] [threaten.py:317] [threaten:sear_info] [ERROR]- 解析威胁情报详细数据报错：'geo'
[2020-06-19 10:05:12,136] [threaten.py:317] [threaten:sear_info] [ERROR]- 解析威胁情报详细数据报错：'geo'
[2020-06-19 10:05:12,136] [threaten.py:317] [threaten:sear_info] [ERROR]- 解析威胁情报详细数据报错：'geo'
[2020-06-19 10:05:12,136] [threaten.py:317] [threaten:sear_info] [ERROR]- 解析威胁情报详细数据报错：'geo'
[2020-06-19 10:05:12,136] [threaten.py:317] [threaten:sear_info] [ERROR]- 解析威胁情报详细数据报错：'geo'
[2020-06-19 10:05:12,136] [threaten.py:317] [threaten:sear_info] [ERROR]- 解析威胁情报详细数据报错：'geo'
[2020-06-19 10:05:12,137] [threaten.py:317] [threaten:sear_info] [ERROR]- 解析威胁情报详细数据报错：'geo'
[2020-06-19 10:05:12,137] [threaten.py:317] [threaten:sear_info] [ERROR]- 解析威胁情报详细数据报错：'geo'
[2020-06-19 10:05:12,137] [threaten.py:317] [threaten:sear_info] [ERROR]- 解析威胁情报详细数据报错：'geo'
[2020-06-19 10:05:12,137] [threaten.py:317] [threaten:sear_info] [ERROR]- 解析威胁情报详细数据报错：'geo'
[2020-06-19 10:05:12,138] [threaten.py:317] [threaten:sear_info] [ERROR]- 解析威胁情报详细数据报错：'geo'
[2020-06-19 10:05:12,140] [basehttp.py:124] [basehttp:log_message] [INFO]- "GET /web/threaten/indexs?page=3 HTTP/1.1" 200 1515
[2020-06-19 10:05:14,053] [threaten.py:317] [threaten:sear_info] [ERROR]- 解析威胁情报详细数据报错：'geo'
[2020-06-19 10:05:14,053] [threaten.py:317] [threaten:sear_info] [ERROR]- 解析威胁情报详细数据报错：'geo'
[2020-06-19 10:05:14,053] [threaten.py:317] [threaten:sear_info] [ERROR]- 解析威胁情报详细数据报错：'geo'
[2020-06-19 10:05:14,054] [threaten.py:317] [threaten:sear_info] [ERROR]- 解析威胁情报详细数据报错：'geo'
[2020-06-19 10:05:14,054] [threaten.py:317] [threaten:sear_info] [ERROR]- 解析威胁情报详细数据报错：'geo'
[2020-06-19 10:05:14,054] [threaten.py:317] [threaten:sear_info] [ERROR]- 解析威胁情报详细数据报错：'geo'
[2020-06-19 10:05:14,055] [threaten.py:317] [threaten:sear_info] [ERROR]- 解析威胁情报详细数据报错：'geo'
[2020-06-19 10:05:14,055] [threaten.py:317] [threaten:sear_info] [ERROR]- 解析威胁情报详细数据报错：'geo'
[2020-06-19 10:05:14,055] [threaten.py:317] [threaten:sear_info] [ERROR]- 解析威胁情报详细数据报错：'geo'
[2020-06-19 10:05:14,056] [threaten.py:317] [threaten:sear_info] [ERROR]- 解析威胁情报详细数据报错：'geo'
[2020-06-19 10:05:14,056] [threaten.py:317] [threaten:sear_info] [ERROR]- 解析威胁情报详细数据报错：'geo'
[2020-06-19 10:05:14,056] [threaten.py:317] [threaten:sear_info] [ERROR]- 解析威胁情报详细数据报错：'geo'
[2020-06-19 10:05:14,056] [threaten.py:317] [threaten:sear_info] [ERROR]- 解析威胁情报详细数据报错：'geo'
[2020-06-19 10:05:14,057] [threaten.py:317] [threaten:sear_info] [ERROR]- 解析威胁情报详细数据报错：'geo'
[2020-06-19 10:05:14,057] [threaten.py:317] [threaten:sear_info] [ERROR]- 解析威胁情报详细数据报错：'geo'
[2020-06-19 10:05:14,057] [threaten.py:317] [threaten:sear_info] [ERROR]- 解析威胁情报详细数据报错：'geo'
[2020-06-19 10:05:14,058] [basehttp.py:124] [basehttp:log_message] [INFO]- "GET /web/threaten/indexs?page=4 HTTP/1.1" 200 662
[2020-06-19 10:05:15,755] [threaten.py:317] [threaten:sear_info] [ERROR]- 解析威胁情报详细数据报错：'geo'
[2020-06-19 10:05:15,755] [threaten.py:317] [threaten:sear_info] [ERROR]- 解析威胁情报详细数据报错：'geo'
[2020-06-19 10:05:15,756] [threaten.py:317] [threaten:sear_info] [ERROR]- 解析威胁情报详细数据报错：'geo'
[2020-06-19 10:05:15,756] [threaten.py:317] [threaten:sear_info] [ERROR]- 解析威胁情报详细数据报错：'geo'
[2020-06-19 10:05:15,756] [threaten.py:317] [threaten:sear_info] [ERROR]- 解析威胁情报详细数据报错：'geo'
[2020-06-19 10:05:15,756] [threaten.py:317] [threaten:sear_info] [ERROR]- 解析威胁情报详细数据报错：'geo'
[2020-06-19 10:05:15,757] [threaten.py:317] [threaten:sear_info] [ERROR]- 解析威胁情报详细数据报错：'geo'
[2020-06-19 10:05:15,757] [threaten.py:317] [threaten:sear_info] [ERROR]- 解析威胁情报详细数据报错：'geo'
[2020-06-19 10:05:15,757] [threaten.py:317] [threaten:sear_info] [ERROR]- 解析威胁情报详细数据报错：'geo'
[2020-06-19 10:05:15,757] [threaten.py:317] [threaten:sear_info] [ERROR]- 解析威胁情报详细数据报错：'geo'
[2020-06-19 10:05:15,757] [threaten.py:317] [threaten:sear_info] [ERROR]- 解析威胁情报详细数据报错：'geo'
[2020-06-19 10:05:15,758] [threaten.py:317] [threaten:sear_info] [ERROR]- 解析威胁情报详细数据报错：'geo'
[2020-06-19 10:05:15,758] [threaten.py:317] [threaten:sear_info] [ERROR]- 解析威胁情报详细数据报错：'geo'
[2020-06-19 10:05:15,758] [threaten.py:317] [threaten:sear_info] [ERROR]- 解析威胁情报详细数据报错：'geo'
[2020-06-19 10:05:15,758] [threaten.py:317] [threaten:sear_info] [ERROR]- 解析威胁情报详细数据报错：'geo'
[2020-06-19 10:05:15,759] [threaten.py:317] [threaten:sear_info] [ERROR]- 解析威胁情报详细数据报错：'geo'
[2020-06-19 10:05:15,760] [basehttp.py:124] [basehttp:log_message] [INFO]- "GET /web/threaten/indexs?page=3 HTTP/1.1" 200 1515
[2020-06-19 10:05:18,546] [threaten.py:317] [threaten:sear_info] [ERROR]- 解析威胁情报详细数据报错：'geo'
[2020-06-19 10:05:18,547] [threaten.py:317] [threaten:sear_info] [ERROR]- 解析威胁情报详细数据报错：'geo'
[2020-06-19 10:05:18,547] [threaten.py:317] [threaten:sear_info] [ERROR]- 解析威胁情报详细数据报错：'geo'
[2020-06-19 10:05:18,547] [threaten.py:317] [threaten:sear_info] [ERROR]- 解析威胁情报详细数据报错：'geo'
[2020-06-19 10:05:18,548] [threaten.py:317] [threaten:sear_info] [ERROR]- 解析威胁情报详细数据报错：'geo'
[2020-06-19 10:05:18,548] [threaten.py:317] [threaten:sear_info] [ERROR]- 解析威胁情报详细数据报错：'geo'
[2020-06-19 10:05:18,548] [threaten.py:317] [threaten:sear_info] [ERROR]- 解析威胁情报详细数据报错：'geo'
[2020-06-19 10:05:18,548] [threaten.py:317] [threaten:sear_info] [ERROR]- 解析威胁情报详细数据报错：'geo'
[2020-06-19 10:05:18,548] [threaten.py:317] [threaten:sear_info] [ERROR]- 解析威胁情报详细数据报错：'geo'
[2020-06-19 10:05:18,549] [threaten.py:317] [threaten:sear_info] [ERROR]- 解析威胁情报详细数据报错：'geo'
[2020-06-19 10:05:18,549] [threaten.py:317] [threaten:sear_info] [ERROR]- 解析威胁情报详细数据报错：'geo'
[2020-06-19 10:05:18,549] [threaten.py:317] [threaten:sear_info] [ERROR]- 解析威胁情报详细数据报错：'geo'
[2020-06-19 10:05:18,549] [threaten.py:317] [threaten:sear_info] [ERROR]- 解析威胁情报详细数据报错：'geo'
[2020-06-19 10:05:18,550] [threaten.py:317] [threaten:sear_info] [ERROR]- 解析威胁情报详细数据报错：'geo'
[2020-06-19 10:05:18,550] [threaten.py:317] [threaten:sear_info] [ERROR]- 解析威胁情报详细数据报错：'geo'
[2020-06-19 10:05:18,550] [threaten.py:317] [threaten:sear_info] [ERROR]- 解析威胁情报详细数据报错：'geo'
[2020-06-19 10:05:18,551] [basehttp.py:124] [basehttp:log_message] [INFO]- "GET /web/threaten/indexs?page=1 HTTP/1.1" 200 1529
[2020-06-19 10:05:19,528] [threaten.py:317] [threaten:sear_info] [ERROR]- 解析威胁情报详细数据报错：'geo'
[2020-06-19 10:05:19,528] [threaten.py:317] [threaten:sear_info] [ERROR]- 解析威胁情报详细数据报错：'geo'
[2020-06-19 10:05:19,528] [threaten.py:317] [threaten:sear_info] [ERROR]- 解析威胁情报详细数据报错：'geo'
[2020-06-19 10:05:19,528] [threaten.py:317] [threaten:sear_info] [ERROR]- 解析威胁情报详细数据报错：'geo'
[2020-06-19 10:05:19,529] [threaten.py:317] [threaten:sear_info] [ERROR]- 解析威胁情报详细数据报错：'geo'
[2020-06-19 10:05:19,529] [threaten.py:317] [threaten:sear_info] [ERROR]- 解析威胁情报详细数据报错：'geo'
[2020-06-19 10:05:19,529] [threaten.py:317] [threaten:sear_info] [ERROR]- 解析威胁情报详细数据报错：'geo'
[2020-06-19 10:05:19,529] [threaten.py:317] [threaten:sear_info] [ERROR]- 解析威胁情报详细数据报错：'geo'
[2020-06-19 10:05:19,530] [threaten.py:317] [threaten:sear_info] [ERROR]- 解析威胁情报详细数据报错：'geo'
[2020-06-19 10:05:19,530] [threaten.py:317] [threaten:sear_info] [ERROR]- 解析威胁情报详细数据报错：'geo'
[2020-06-19 10:05:19,530] [threaten.py:317] [threaten:sear_info] [ERROR]- 解析威胁情报详细数据报错：'geo'
[2020-06-19 10:05:19,530] [threaten.py:317] [threaten:sear_info] [ERROR]- 解析威胁情报详细数据报错：'geo'
[2020-06-19 10:05:19,530] [threaten.py:317] [threaten:sear_info] [ERROR]- 解析威胁情报详细数据报错：'geo'
[2020-06-19 10:05:19,530] [threaten.py:317] [threaten:sear_info] [ERROR]- 解析威胁情报详细数据报错：'geo'
[2020-06-19 10:05:19,531] [threaten.py:317] [threaten:sear_info] [ERROR]- 解析威胁情报详细数据报错：'geo'
[2020-06-19 10:05:19,531] [threaten.py:317] [threaten:sear_info] [ERROR]- 解析威胁情报详细数据报错：'geo'
[2020-06-19 10:05:19,533] [basehttp.py:124] [basehttp:log_message] [INFO]- "GET /web/threaten/indexs?page=2 HTTP/1.1" 200 1504
[2020-06-19 10:05:20,862] [threaten.py:317] [threaten:sear_info] [ERROR]- 解析威胁情报详细数据报错：'geo'
[2020-06-19 10:05:20,862] [threaten.py:317] [threaten:sear_info] [ERROR]- 解析威胁情报详细数据报错：'geo'
[2020-06-19 10:05:20,863] [threaten.py:317] [threaten:sear_info] [ERROR]- 解析威胁情报详细数据报错：'geo'
[2020-06-19 10:05:20,863] [threaten.py:317] [threaten:sear_info] [ERROR]- 解析威胁情报详细数据报错：'geo'
[2020-06-19 10:05:20,863] [threaten.py:317] [threaten:sear_info] [ERROR]- 解析威胁情报详细数据报错：'geo'
[2020-06-19 10:05:20,863] [threaten.py:317] [threaten:sear_info] [ERROR]- 解析威胁情报详细数据报错：'geo'
[2020-06-19 10:05:20,863] [threaten.py:317] [threaten:sear_info] [ERROR]- 解析威胁情报详细数据报错：'geo'
[2020-06-19 10:05:20,863] [threaten.py:317] [threaten:sear_info] [ERROR]- 解析威胁情报详细数据报错：'geo'
[2020-06-19 10:05:20,864] [threaten.py:317] [threaten:sear_info] [ERROR]- 解析威胁情报详细数据报错：'geo'
[2020-06-19 10:05:20,864] [threaten.py:317] [threaten:sear_info] [ERROR]- 解析威胁情报详细数据报错：'geo'
[2020-06-19 10:05:20,864] [threaten.py:317] [threaten:sear_info] [ERROR]- 解析威胁情报详细数据报错：'geo'
[2020-06-19 10:05:20,865] [threaten.py:317] [threaten:sear_info] [ERROR]- 解析威胁情报详细数据报错：'geo'
[2020-06-19 10:05:20,865] [threaten.py:317] [threaten:sear_info] [ERROR]- 解析威胁情报详细数据报错：'geo'
[2020-06-19 10:05:20,865] [threaten.py:317] [threaten:sear_info] [ERROR]- 解析威胁情报详细数据报错：'geo'
[2020-06-19 10:05:20,865] [threaten.py:317] [threaten:sear_info] [ERROR]- 解析威胁情报详细数据报错：'geo'
[2020-06-19 10:05:20,866] [threaten.py:317] [threaten:sear_info] [ERROR]- 解析威胁情报详细数据报错：'geo'
[2020-06-19 10:05:20,867] [basehttp.py:124] [basehttp:log_message] [INFO]- "GET /web/threaten/indexs?page=3 HTTP/1.1" 200 1515
[2020-06-19 10:05:21,233] [threaten.py:317] [threaten:sear_info] [ERROR]- 解析威胁情报详细数据报错：'geo'
[2020-06-19 10:05:21,233] [threaten.py:317] [threaten:sear_info] [ERROR]- 解析威胁情报详细数据报错：'geo'
[2020-06-19 10:05:21,233] [threaten.py:317] [threaten:sear_info] [ERROR]- 解析威胁情报详细数据报错：'geo'
[2020-06-19 10:05:21,233] [threaten.py:317] [threaten:sear_info] [ERROR]- 解析威胁情报详细数据报错：'geo'
[2020-06-19 10:05:21,234] [threaten.py:317] [threaten:sear_info] [ERROR]- 解析威胁情报详细数据报错：'geo'
[2020-06-19 10:05:21,234] [threaten.py:317] [threaten:sear_info] [ERROR]- 解析威胁情报详细数据报错：'geo'
[2020-06-19 10:05:21,234] [threaten.py:317] [threaten:sear_info] [ERROR]- 解析威胁情报详细数据报错：'geo'
[2020-06-19 10:05:21,234] [threaten.py:317] [threaten:sear_info] [ERROR]- 解析威胁情报详细数据报错：'geo'
[2020-06-19 10:05:21,235] [threaten.py:317] [threaten:sear_info] [ERROR]- 解析威胁情报详细数据报错：'geo'
[2020-06-19 10:05:21,235] [threaten.py:317] [threaten:sear_info] [ERROR]- 解析威胁情报详细数据报错：'geo'
[2020-06-19 10:05:21,235] [threaten.py:317] [threaten:sear_info] [ERROR]- 解析威胁情报详细数据报错：'geo'
[2020-06-19 10:05:21,235] [threaten.py:317] [threaten:sear_info] [ERROR]- 解析威胁情报详细数据报错：'geo'
[2020-06-19 10:05:21,236] [threaten.py:317] [threaten:sear_info] [ERROR]- 解析威胁情报详细数据报错：'geo'
[2020-06-19 10:05:21,236] [threaten.py:317] [threaten:sear_info] [ERROR]- 解析威胁情报详细数据报错：'geo'
[2020-06-19 10:05:21,236] [threaten.py:317] [threaten:sear_info] [ERROR]- 解析威胁情报详细数据报错：'geo'
[2020-06-19 10:05:21,237] [threaten.py:317] [threaten:sear_info] [ERROR]- 解析威胁情报详细数据报错：'geo'
[2020-06-19 10:05:21,238] [basehttp.py:124] [basehttp:log_message] [INFO]- "GET /web/threaten/indexs?page=4 HTTP/1.1" 200 662
[2020-06-19 10:05:44,958] [basehttp.py:124] [basehttp:log_message] [INFO]- "GET /web/attackmap HTTP/1.1" 200 4338
[2020-06-19 10:06:06,013] [threaten.py:317] [threaten:sear_info] [ERROR]- 解析威胁情报详细数据报错：'geo'
[2020-06-19 10:06:06,013] [threaten.py:317] [threaten:sear_info] [ERROR]- 解析威胁情报详细数据报错：'geo'
[2020-06-19 10:06:06,014] [threaten.py:317] [threaten:sear_info] [ERROR]- 解析威胁情报详细数据报错：'geo'
[2020-06-19 10:06:06,014] [threaten.py:317] [threaten:sear_info] [ERROR]- 解析威胁情报详细数据报错：'geo'
[2020-06-19 10:06:06,014] [threaten.py:317] [threaten:sear_info] [ERROR]- 解析威胁情报详细数据报错：'geo'
[2020-06-19 10:06:06,014] [threaten.py:317] [threaten:sear_info] [ERROR]- 解析威胁情报详细数据报错：'geo'
[2020-06-19 10:06:06,020] [basehttp.py:124] [basehttp:log_message] [INFO]- "GET /web/threaten/indexs?pIndex=0 HTTP/1.1" 200 13115
[2020-06-19 10:06:07,453] [basehttp.py:124] [basehttp:log_message] [INFO]- "GET /web/threaten/thattack HTTP/1.1" 200 564
[2020-06-19 10:06:07,467] [basehttp.py:124] [basehttp:log_message] [INFO]- "GET /web/threaten/thhit HTTP/1.1" 200 770
[2020-06-19 10:06:07,475] [basehttp.py:124] [basehttp:log_message] [INFO]- "GET /web/threaten/threat HTTP/1.1" 200 998
[2020-06-19 10:06:07,478] [basehttp.py:124] [basehttp:log_message] [INFO]- "GET /web/threaten/thactive HTTP/1.1" 200 280
[2020-06-19 10:06:09,775] [threaten.py:317] [threaten:sear_info] [ERROR]- 解析威胁情报详细数据报错：'geo'
[2020-06-19 10:06:09,776] [threaten.py:317] [threaten:sear_info] [ERROR]- 解析威胁情报详细数据报错：'geo'
[2020-06-19 10:06:09,777] [threaten.py:317] [threaten:sear_info] [ERROR]- 解析威胁情报详细数据报错：'geo'
[2020-06-19 10:06:09,777] [threaten.py:317] [threaten:sear_info] [ERROR]- 解析威胁情报详细数据报错：'geo'
[2020-06-19 10:06:09,777] [threaten.py:317] [threaten:sear_info] [ERROR]- 解析威胁情报详细数据报错：'geo'
[2020-06-19 10:06:09,778] [threaten.py:317] [threaten:sear_info] [ERROR]- 解析威胁情报详细数据报错：'geo'
[2020-06-19 10:06:09,780] [basehttp.py:124] [basehttp:log_message] [INFO]- "GET /web/threaten/indexs?page=1 HTTP/1.1" 200 1510
[2020-06-19 10:06:18,745] [basehttp.py:124] [basehttp:log_message] [INFO]- "GET /web/Hit HTTP/1.1" 200 37
[2020-06-19 10:06:18,776] [threaten.py:317] [threaten:sear_info] [ERROR]- 解析威胁情报详细数据报错：'geo'
[2020-06-19 10:06:18,776] [threaten.py:317] [threaten:sear_info] [ERROR]- 解析威胁情报详细数据报错：'geo'
[2020-06-19 10:06:18,777] [threaten.py:317] [threaten:sear_info] [ERROR]- 解析威胁情报详细数据报错：'geo'
[2020-06-19 10:06:18,777] [threaten.py:317] [threaten:sear_info] [ERROR]- 解析威胁情报详细数据报错：'geo'
[2020-06-19 10:06:18,777] [threaten.py:317] [threaten:sear_info] [ERROR]- 解析威胁情报详细数据报错：'geo'
[2020-06-19 10:06:18,778] [threaten.py:317] [threaten:sear_info] [ERROR]- 解析威胁情报详细数据报错：'geo'
[2020-06-19 10:06:18,780] [basehttp.py:124] [basehttp:log_message] [INFO]- "GET /web/threaten/indexs?page=5 HTTP/1.1" 200 645
[2020-06-19 10:06:18,782] [threaten.py:317] [threaten:sear_info] [ERROR]- 解析威胁情报详细数据报错：'geo'
[2020-06-19 10:06:18,782] [threaten.py:317] [threaten:sear_info] [ERROR]- 解析威胁情报详细数据报错：'geo'
[2020-06-19 10:06:18,782] [threaten.py:317] [threaten:sear_info] [ERROR]- 解析威胁情报详细数据报错：'geo'
[2020-06-19 10:06:18,782] [threaten.py:317] [threaten:sear_info] [ERROR]- 解析威胁情报详细数据报错：'geo'
[2020-06-19 10:06:18,782] [threaten.py:317] [threaten:sear_info] [ERROR]- 解析威胁情报详细数据报错：'geo'
[2020-06-19 10:06:18,782] [threaten.py:317] [threaten:sear_info] [ERROR]- 解析威胁情报详细数据报错：'geo'
[2020-06-19 10:06:18,784] [basehttp.py:124] [basehttp:log_message] [INFO]- "GET /web/threaten/indexs?page=1 HTTP/1.1" 200 1510
[2020-06-19 10:06:18,785] [basehttp.py:124] [basehttp:log_message] [INFO]- "GET /web/threaten/thnews HTTP/1.1" 200 1023
[2020-06-19 10:06:21,509] [threaten.py:317] [threaten:sear_info] [ERROR]- 解析威胁情报详细数据报错：'geo'
[2020-06-19 10:06:21,510] [threaten.py:317] [threaten:sear_info] [ERROR]- 解析威胁情报详细数据报错：'geo'
[2020-06-19 10:06:21,510] [threaten.py:317] [threaten:sear_info] [ERROR]- 解析威胁情报详细数据报错：'geo'
[2020-06-19 10:06:21,510] [threaten.py:317] [threaten:sear_info] [ERROR]- 解析威胁情报详细数据报错：'geo'
[2020-06-19 10:06:21,511] [threaten.py:317] [threaten:sear_info] [ERROR]- 解析威胁情报详细数据报错：'geo'
[2020-06-19 10:06:21,511] [threaten.py:317] [threaten:sear_info] [ERROR]- 解析威胁情报详细数据报错：'geo'
[2020-06-19 10:06:21,513] [basehttp.py:124] [basehttp:log_message] [INFO]- "GET /web/threaten/indexs?page=5 HTTP/1.1" 200 645
[2020-06-19 10:06:35,983] [threaten.py:317] [threaten:sear_info] [ERROR]- 解析威胁情报详细数据报错：'geo'
[2020-06-19 10:06:35,983] [threaten.py:317] [threaten:sear_info] [ERROR]- 解析威胁情报详细数据报错：'geo'
[2020-06-19 10:06:35,983] [threaten.py:317] [threaten:sear_info] [ERROR]- 解析威胁情报详细数据报错：'geo'
[2020-06-19 10:06:35,983] [threaten.py:317] [threaten:sear_info] [ERROR]- 解析威胁情报详细数据报错：'geo'
[2020-06-19 10:06:35,983] [threaten.py:317] [threaten:sear_info] [ERROR]- 解析威胁情报详细数据报错：'geo'
[2020-06-19 10:06:35,984] [threaten.py:317] [threaten:sear_info] [ERROR]- 解析威胁情报详细数据报错：'geo'
[2020-06-19 10:06:35,986] [basehttp.py:124] [basehttp:log_message] [INFO]- "GET /web/threaten/indexs?page=2 HTTP/1.1" 200 1490
[2020-06-19 10:07:11,333] [basehttp.py:124] [basehttp:log_message] [INFO]- "GET /web/threaten/indexs?pIndex=0 HTTP/1.1" 200 13115
[2020-06-19 10:07:12,772] [basehttp.py:124] [basehttp:log_message] [INFO]- "GET /web/threaten/thattack HTTP/1.1" 200 564
[2020-06-19 10:07:12,784] [basehttp.py:124] [basehttp:log_message] [INFO]- "GET /web/threaten/indexs?page=1 HTTP/1.1" 200 1509
[2020-06-19 10:07:12,786] [basehttp.py:124] [basehttp:log_message] [INFO]- "GET /web/Hit HTTP/1.1" 200 37
[2020-06-19 10:07:12,795] [basehttp.py:124] [basehttp:log_message] [INFO]- "GET /web/threaten/thactive HTTP/1.1" 200 280
[2020-06-19 10:07:12,803] [basehttp.py:124] [basehttp:log_message] [INFO]- "GET /web/threaten/thhit HTTP/1.1" 200 770
[2020-06-19 10:07:12,805] [basehttp.py:124] [basehttp:log_message] [INFO]- "GET /web/threaten/threat HTTP/1.1" 200 998
[2020-06-19 10:07:12,836] [basehttp.py:124] [basehttp:log_message] [INFO]- "GET /web/threaten/thnews HTTP/1.1" 200 1023
[2020-06-19 10:07:16,490] [basehttp.py:124] [basehttp:log_message] [INFO]- "GET /web/threaten/indexs?page=2 HTTP/1.1" 200 1475
[2020-06-19 10:07:19,665] [basehttp.py:124] [basehttp:log_message] [INFO]- "GET /web/threaten/indexs?page=3 HTTP/1.1" 200 1525
[2020-06-19 10:07:21,844] [basehttp.py:124] [basehttp:log_message] [INFO]- "GET /web/threaten/indexs?page=4 HTTP/1.1" 200 1509
[2020-06-19 10:07:49,032] [basehttp.py:124] [basehttp:log_message] [INFO]- "GET /web/threaten/indexs?page=2 HTTP/1.1" 200 1475
[2020-06-19 10:07:49,844] [basehttp.py:124] [basehttp:log_message] [INFO]- "GET /web/threaten/indexs?page=3 HTTP/1.1" 200 1525
[2020-06-19 10:07:50,456] [basehttp.py:124] [basehttp:log_message] [INFO]- "GET /web/threaten/indexs?page=1 HTTP/1.1" 200 1509
[2020-06-19 10:07:51,224] [basehttp.py:124] [basehttp:log_message] [INFO]- "GET /web/threaten/indexs?page=3 HTTP/1.1" 200 1525
[2020-06-19 10:07:51,712] [basehttp.py:124] [basehttp:log_message] [INFO]- "GET /web/threaten/indexs?page=4 HTTP/1.1" 200 1509
[2020-06-19 10:25:20,895] [threaten.py:313] [threaten:sear_info] [ERROR]- 解析威胁情报详细数据报错：'geo'
[2020-06-19 10:25:20,895] [threaten.py:313] [threaten:sear_info] [ERROR]- 解析威胁情报详细数据报错：'geo'
[2020-06-19 10:25:20,895] [threaten.py:313] [threaten:sear_info] [ERROR]- 解析威胁情报详细数据报错：'geo'
[2020-06-19 10:25:20,895] [threaten.py:313] [threaten:sear_info] [ERROR]- 解析威胁情报详细数据报错：'geo'
[2020-06-19 10:25:20,896] [threaten.py:313] [threaten:sear_info] [ERROR]- 解析威胁情报详细数据报错：'geo'
[2020-06-19 10:25:20,912] [basehttp.py:124] [basehttp:log_message] [INFO]- "GET /web/threaten/indexs?pIndex=0 HTTP/1.1" 200 13115
[2020-06-19 10:25:22,981] [basehttp.py:124] [basehttp:log_message] [INFO]- "GET /web/threaten/thattack HTTP/1.1" 200 564
[2020-06-19 10:25:22,982] [threaten.py:313] [threaten:sear_info] [ERROR]- 解析威胁情报详细数据报错：'geo'
[2020-06-19 10:25:22,984] [threaten.py:313] [threaten:sear_info] [ERROR]- 解析威胁情报详细数据报错：'geo'
[2020-06-19 10:25:22,984] [threaten.py:313] [threaten:sear_info] [ERROR]- 解析威胁情报详细数据报错：'geo'
[2020-06-19 10:25:22,984] [threaten.py:313] [threaten:sear_info] [ERROR]- 解析威胁情报详细数据报错：'geo'
[2020-06-19 10:25:22,985] [threaten.py:313] [threaten:sear_info] [ERROR]- 解析威胁情报详细数据报错：'geo'
[2020-06-19 10:25:22,986] [basehttp.py:124] [basehttp:log_message] [INFO]- "GET /web/threaten/indexs?page=1 HTTP/1.1" 200 1562
[2020-06-19 10:25:22,996] [basehttp.py:124] [basehttp:log_message] [INFO]- "GET /web/threaten/thhit HTTP/1.1" 200 770
[2020-06-19 10:25:23,002] [basehttp.py:124] [basehttp:log_message] [INFO]- "GET /web/threaten/threat HTTP/1.1" 200 998
[2020-06-19 10:25:23,004] [basehttp.py:124] [basehttp:log_message] [INFO]- "GET /web/threaten/thactive HTTP/1.1" 200 280
[2020-06-19 10:25:25,272] [basehttp.py:124] [basehttp:log_message] [INFO]- "GET /web/Hit HTTP/1.1" 200 37
[2020-06-19 10:25:25,312] [basehttp.py:124] [basehttp:log_message] [INFO]- "GET /web/threaten/thnews HTTP/1.1" 200 1023
[2020-06-19 10:26:53,186] [threaten.py:310] [threaten:sear_info] [ERROR]- 解析威胁情报详细数据报错：'geo'
[2020-06-19 10:26:53,187] [threaten.py:310] [threaten:sear_info] [ERROR]- 解析威胁情报详细数据报错：'geo'
[2020-06-19 10:26:53,202] [basehttp.py:124] [basehttp:log_message] [INFO]- "GET /web/threaten/indexs?pIndex=0 HTTP/1.1" 200 13352
[2020-06-19 10:27:05,252] [threaten.py:310] [threaten:sear_info] [ERROR]- 解析威胁情报详细数据报错：'geo'
[2020-06-19 10:27:05,252] [threaten.py:310] [threaten:sear_info] [ERROR]- 解析威胁情报详细数据报错：'geo'
[2020-06-19 10:27:05,253] [basehttp.py:124] [basehttp:log_message] [INFO]- "GET /web/threaten/indexs?page=1 HTTP/1.1" 200 1237
[2020-06-19 10:27:05,269] [basehttp.py:124] [basehttp:log_message] [INFO]- "GET /web/threaten/thattack HTTP/1.1" 200 564
[2020-06-19 10:27:05,283] [basehttp.py:124] [basehttp:log_message] [INFO]- "GET /web/threaten/threat HTTP/1.1" 200 998
[2020-06-19 10:27:05,285] [basehttp.py:124] [basehttp:log_message] [INFO]- "GET /web/threaten/thhit HTTP/1.1" 200 769
[2020-06-19 10:27:05,289] [basehttp.py:124] [basehttp:log_message] [INFO]- "GET /web/threaten/thactive HTTP/1.1" 200 280
[2020-06-19 10:27:07,541] [basehttp.py:124] [basehttp:log_message] [INFO]- "GET /web/Hit HTTP/1.1" 200 37
[2020-06-19 10:27:07,565] [basehttp.py:124] [basehttp:log_message] [INFO]- "GET /web/threaten/thnews HTTP/1.1" 200 1023
[2020-06-19 10:27:12,327] [threaten.py:310] [threaten:sear_info] [ERROR]- 解析威胁情报详细数据报错：'geo'
[2020-06-19 10:27:12,328] [threaten.py:310] [threaten:sear_info] [ERROR]- 解析威胁情报详细数据报错：'geo'
[2020-06-19 10:27:12,329] [basehttp.py:124] [basehttp:log_message] [INFO]- "GET /web/threaten/indexs?page=2 HTTP/1.1" 200 1275
[2020-06-19 10:27:13,812] [threaten.py:310] [threaten:sear_info] [ERROR]- 解析威胁情报详细数据报错：'geo'
[2020-06-19 10:27:13,813] [threaten.py:310] [threaten:sear_info] [ERROR]- 解析威胁情报详细数据报错：'geo'
[2020-06-19 10:27:13,813] [basehttp.py:124] [basehttp:log_message] [INFO]- "GET /web/threaten/indexs?page=3 HTTP/1.1" 200 1234
[2020-06-19 10:27:15,004] [threaten.py:310] [threaten:sear_info] [ERROR]- 解析威胁情报详细数据报错：'geo'
[2020-06-19 10:27:15,004] [threaten.py:310] [threaten:sear_info] [ERROR]- 解析威胁情报详细数据报错：'geo'
[2020-06-19 10:27:15,005] [basehttp.py:124] [basehttp:log_message] [INFO]- "GET /web/threaten/indexs?page=4 HTTP/1.1" 200 1219
[2020-06-19 10:28:01,852] [threaten.py:310] [threaten:sear_info] [ERROR]- 解析威胁情报详细数据报错：'geo'
[2020-06-19 10:28:01,853] [threaten.py:310] [threaten:sear_info] [ERROR]- 解析威胁情报详细数据报错：'geo'
[2020-06-19 10:28:01,869] [basehttp.py:124] [basehttp:log_message] [INFO]- "GET /web/threaten/indexs?pIndex=0 HTTP/1.1" 200 13352
[2020-06-19 10:28:03,211] [basehttp.py:124] [basehttp:log_message] [INFO]- "GET /web/threaten/indexs?page=1 HTTP/1.1" 200 1137
[2020-06-19 10:28:03,215] [basehttp.py:124] [basehttp:log_message] [INFO]- "GET /web/threaten/thattack HTTP/1.1" 200 564
[2020-06-19 10:28:03,252] [basehttp.py:124] [basehttp:log_message] [INFO]- "GET /web/threaten/thhit HTTP/1.1" 200 769
[2020-06-19 10:28:03,257] [basehttp.py:124] [basehttp:log_message] [INFO]- "GET /web/threaten/threat HTTP/1.1" 200 998
[2020-06-19 10:28:03,257] [basehttp.py:124] [basehttp:log_message] [INFO]- "GET /web/threaten/thactive HTTP/1.1" 200 280
[2020-06-19 10:36:57,209] [basehttp.py:124] [basehttp:log_message] [INFO]- "GET /static/monit/js/jquery.min.map HTTP/1.1" 200 127588
[2020-06-19 10:37:00,143] [exception.py:135] [exception:handle_uncaught_exception] [ERROR]- Internal Server Error: /web/threaten/indexs
Traceback (most recent call last):
  File "E:\project_env\lib\site-packages\django\core\handlers\exception.py", line 41, in inner
    response = get_response(request)
  File "E:\project_env\lib\site-packages\django\core\handlers\base.py", line 187, in _get_response
    response = self.process_exception_by_middleware(e, request)
  File "E:\project_env\lib\site-packages\django\core\handlers\base.py", line 185, in _get_response
    response = wrapped_callback(request, *callback_args, **callback_kwargs)
  File "E:\project_env\lib\site-packages\django\views\generic\base.py", line 68, in view
    return self.dispatch(request, *args, **kwargs)
  File "E:\project_env\lib\site-packages\django\views\generic\base.py", line 88, in dispatch
    return handler(request, *args, **kwargs)
  File "E:\monitor\HqMonitor\web\views\threaten.py", line 32, in get
    result =self.seardat(pIndex)
  File "E:\monitor\HqMonitor\web\views\threaten.py", line 91, in seardat
    if int(comid) == 0:  # 是否携带用户信息
TypeError: int() argument must be a string, a bytes-like object or a number, not 'NoneType'
[2020-06-19 10:37:00,227] [basehttp.py:124] [basehttp:log_message] [ERROR]- "GET /web/threaten/indexs?page=2 HTTP/1.1" 500 16703
[2020-06-19 10:37:03,001] [exception.py:135] [exception:handle_uncaught_exception] [ERROR]- Internal Server Error: /web/threaten/indexs
Traceback (most recent call last):
  File "E:\project_env\lib\site-packages\django\core\handlers\exception.py", line 41, in inner
    response = get_response(request)
  File "E:\project_env\lib\site-packages\django\core\handlers\base.py", line 187, in _get_response
    response = self.process_exception_by_middleware(e, request)
  File "E:\project_env\lib\site-packages\django\core\handlers\base.py", line 185, in _get_response
    response = wrapped_callback(request, *callback_args, **callback_kwargs)
  File "E:\project_env\lib\site-packages\django\views\generic\base.py", line 68, in view
    return self.dispatch(request, *args, **kwargs)
  File "E:\project_env\lib\site-packages\django\views\generic\base.py", line 88, in dispatch
    return handler(request, *args, **kwargs)
  File "E:\monitor\HqMonitor\web\views\threaten.py", line 32, in get
    result =self.seardat(pIndex)
  File "E:\monitor\HqMonitor\web\views\threaten.py", line 91, in seardat
    if int(comid) == 0:  # 是否携带用户信息
TypeError: int() argument must be a string, a bytes-like object or a number, not 'NoneType'
[2020-06-19 10:37:03,010] [basehttp.py:124] [basehttp:log_message] [ERROR]- "GET /web/threaten/indexs?page=3 HTTP/1.1" 500 16702
[2020-06-19 10:37:04,321] [exception.py:135] [exception:handle_uncaught_exception] [ERROR]- Internal Server Error: /web/threaten/indexs
Traceback (most recent call last):
  File "E:\project_env\lib\site-packages\django\core\handlers\exception.py", line 41, in inner
    response = get_response(request)
  File "E:\project_env\lib\site-packages\django\core\handlers\base.py", line 187, in _get_response
    response = self.process_exception_by_middleware(e, request)
  File "E:\project_env\lib\site-packages\django\core\handlers\base.py", line 185, in _get_response
    response = wrapped_callback(request, *callback_args, **callback_kwargs)
  File "E:\project_env\lib\site-packages\django\views\generic\base.py", line 68, in view
    return self.dispatch(request, *args, **kwargs)
  File "E:\project_env\lib\site-packages\django\views\generic\base.py", line 88, in dispatch
    return handler(request, *args, **kwargs)
  File "E:\monitor\HqMonitor\web\views\threaten.py", line 32, in get
    result =self.seardat(pIndex)
  File "E:\monitor\HqMonitor\web\views\threaten.py", line 91, in seardat
    if int(comid) == 0:  # 是否携带用户信息
TypeError: int() argument must be a string, a bytes-like object or a number, not 'NoneType'
[2020-06-19 10:37:04,329] [basehttp.py:124] [basehttp:log_message] [ERROR]- "GET /web/threaten/indexs?page=2 HTTP/1.1" 500 16703
[2020-06-19 10:37:05,209] [exception.py:135] [exception:handle_uncaught_exception] [ERROR]- Internal Server Error: /web/threaten/indexs
Traceback (most recent call last):
  File "E:\project_env\lib\site-packages\django\core\handlers\exception.py", line 41, in inner
    response = get_response(request)
  File "E:\project_env\lib\site-packages\django\core\handlers\base.py", line 187, in _get_response
    response = self.process_exception_by_middleware(e, request)
  File "E:\project_env\lib\site-packages\django\core\handlers\base.py", line 185, in _get_response
    response = wrapped_callback(request, *callback_args, **callback_kwargs)
  File "E:\project_env\lib\site-packages\django\views\generic\base.py", line 68, in view
    return self.dispatch(request, *args, **kwargs)
  File "E:\project_env\lib\site-packages\django\views\generic\base.py", line 88, in dispatch
    return handler(request, *args, **kwargs)
  File "E:\monitor\HqMonitor\web\views\threaten.py", line 32, in get
    result =self.seardat(pIndex)
  File "E:\monitor\HqMonitor\web\views\threaten.py", line 91, in seardat
    if int(comid) == 0:  # 是否携带用户信息
TypeError: int() argument must be a string, a bytes-like object or a number, not 'NoneType'
[2020-06-19 10:37:05,218] [basehttp.py:124] [basehttp:log_message] [ERROR]- "GET /web/threaten/indexs?page=1 HTTP/1.1" 500 16702
[2020-06-19 10:37:09,207] [exception.py:135] [exception:handle_uncaught_exception] [ERROR]- Internal Server Error: /web/threaten/indexs
Traceback (most recent call last):
  File "E:\project_env\lib\site-packages\django\core\handlers\exception.py", line 41, in inner
    response = get_response(request)
  File "E:\project_env\lib\site-packages\django\core\handlers\base.py", line 187, in _get_response
    response = self.process_exception_by_middleware(e, request)
  File "E:\project_env\lib\site-packages\django\core\handlers\base.py", line 185, in _get_response
    response = wrapped_callback(request, *callback_args, **callback_kwargs)
  File "E:\project_env\lib\site-packages\django\views\generic\base.py", line 68, in view
    return self.dispatch(request, *args, **kwargs)
  File "E:\project_env\lib\site-packages\django\views\generic\base.py", line 88, in dispatch
    return handler(request, *args, **kwargs)
  File "E:\monitor\HqMonitor\web\views\threaten.py", line 32, in get
    result =self.seardat(pIndex)
  File "E:\monitor\HqMonitor\web\views\threaten.py", line 91, in seardat
    if int(comid) == 0:  # 是否携带用户信息
TypeError: int() argument must be a string, a bytes-like object or a number, not 'NoneType'
[2020-06-19 10:37:09,215] [basehttp.py:124] [basehttp:log_message] [ERROR]- "GET /web/threaten/indexs?page=6 HTTP/1.1" 500 16703
[2020-06-19 10:37:10,663] [exception.py:135] [exception:handle_uncaught_exception] [ERROR]- Internal Server Error: /web/threaten/indexs
Traceback (most recent call last):
  File "E:\project_env\lib\site-packages\django\core\handlers\exception.py", line 41, in inner
    response = get_response(request)
  File "E:\project_env\lib\site-packages\django\core\handlers\base.py", line 187, in _get_response
    response = self.process_exception_by_middleware(e, request)
  File "E:\project_env\lib\site-packages\django\core\handlers\base.py", line 185, in _get_response
    response = wrapped_callback(request, *callback_args, **callback_kwargs)
  File "E:\project_env\lib\site-packages\django\views\generic\base.py", line 68, in view
    return self.dispatch(request, *args, **kwargs)
  File "E:\project_env\lib\site-packages\django\views\generic\base.py", line 88, in dispatch
    return handler(request, *args, **kwargs)
  File "E:\monitor\HqMonitor\web\views\threaten.py", line 32, in get
    result =self.seardat(pIndex)
  File "E:\monitor\HqMonitor\web\views\threaten.py", line 91, in seardat
    if int(comid) == 0:  # 是否携带用户信息
TypeError: int() argument must be a string, a bytes-like object or a number, not 'NoneType'
[2020-06-19 10:37:10,673] [basehttp.py:124] [basehttp:log_message] [ERROR]- "GET /web/threaten/indexs?page=1 HTTP/1.1" 500 16703
[2020-06-19 10:42:02,296] [threaten.py:276] [threaten:sear_info] [ERROR]- 解析威胁情报详细数据报错：'geo'
[2020-06-19 10:42:02,296] [threaten.py:276] [threaten:sear_info] [ERROR]- 解析威胁情报详细数据报错：'geo'
[2020-06-19 10:42:02,310] [basehttp.py:124] [basehttp:log_message] [INFO]- "GET /web/threaten/indexs?pIndex=0 HTTP/1.1" 200 13344
[2020-06-19 10:42:02,374] [exception.py:135] [exception:handle_uncaught_exception] [ERROR]- Internal Server Error: /web/threaten/indexs
Traceback (most recent call last):
  File "E:\project_env\lib\site-packages\django\core\handlers\exception.py", line 41, in inner
    response = get_response(request)
  File "E:\project_env\lib\site-packages\django\core\handlers\base.py", line 187, in _get_response
    response = self.process_exception_by_middleware(e, request)
  File "E:\project_env\lib\site-packages\django\core\handlers\base.py", line 185, in _get_response
    response = wrapped_callback(request, *callback_args, **callback_kwargs)
  File "E:\project_env\lib\site-packages\django\views\generic\base.py", line 68, in view
    return self.dispatch(request, *args, **kwargs)
  File "E:\project_env\lib\site-packages\django\views\generic\base.py", line 88, in dispatch
    return handler(request, *args, **kwargs)
  File "E:\monitor\HqMonitor\web\views\threaten.py", line 32, in get
    result =self.seardat(pIndex)
  File "E:\monitor\HqMonitor\web\views\threaten.py", line 91, in seardat
    if int(comid) == 0:  # 是否携带用户信息
TypeError: int() argument must be a string, a bytes-like object or a number, not 'NoneType'
[2020-06-19 10:42:02,388] [basehttp.py:124] [basehttp:log_message] [ERROR]- "GET /web/threaten/indexs?comid=0&page=1 HTTP/1.1" 500 16731
[2020-06-19 10:42:02,393] [basehttp.py:124] [basehttp:log_message] [INFO]- "GET /web/threaten/thattack HTTP/1.1" 200 564
[2020-06-19 10:42:02,428] [basehttp.py:124] [basehttp:log_message] [INFO]- "GET /web/threaten/thhit HTTP/1.1" 200 769
[2020-06-19 10:42:02,431] [basehttp.py:124] [basehttp:log_message] [INFO]- "GET /web/threaten/thactive HTTP/1.1" 200 280
[2020-06-19 10:42:02,431] [basehttp.py:124] [basehttp:log_message] [INFO]- "GET /web/threaten/threat HTTP/1.1" 200 998
[2020-06-19 10:42:13,710] [basehttp.py:124] [basehttp:log_message] [INFO]- "GET /web/Hit HTTP/1.1" 200 37
[2020-06-19 10:42:13,749] [basehttp.py:124] [basehttp:log_message] [INFO]- "GET /web/threaten/thnews HTTP/1.1" 200 1023
[2020-06-19 10:42:48,766] [exception.py:135] [exception:handle_uncaught_exception] [ERROR]- Internal Server Error: /web/threaten/indexs
Traceback (most recent call last):
  File "E:\project_env\lib\site-packages\django\core\handlers\exception.py", line 41, in inner
    response = get_response(request)
  File "E:\project_env\lib\site-packages\django\core\handlers\base.py", line 187, in _get_response
    response = self.process_exception_by_middleware(e, request)
  File "E:\project_env\lib\site-packages\django\core\handlers\base.py", line 185, in _get_response
    response = wrapped_callback(request, *callback_args, **callback_kwargs)
  File "E:\project_env\lib\site-packages\django\views\generic\base.py", line 68, in view
    return self.dispatch(request, *args, **kwargs)
  File "E:\project_env\lib\site-packages\django\views\generic\base.py", line 88, in dispatch
    return handler(request, *args, **kwargs)
  File "E:\monitor\HqMonitor\web\views\threaten.py", line 31, in get
    result =self.seardat(comid)
  File "E:\monitor\HqMonitor\web\views\threaten.py", line 90, in seardat
    if int(comid) == 0:  # 是否携带用户信息
TypeError: int() argument must be a string, a bytes-like object or a number, not 'NoneType'
[2020-06-19 10:42:48,867] [basehttp.py:124] [basehttp:log_message] [ERROR]- "GET /web/threaten/indexs?pIndex=0 HTTP/1.1" 500 84251
[2020-06-19 10:43:38,649] [threaten.py:275] [threaten:sear_info] [ERROR]- 解析威胁情报详细数据报错：'geo'
[2020-06-19 10:43:38,650] [threaten.py:275] [threaten:sear_info] [ERROR]- 解析威胁情报详细数据报错：'geo'
[2020-06-19 10:43:38,650] [threaten.py:275] [threaten:sear_info] [ERROR]- 解析威胁情报详细数据报错：'geo'
[2020-06-19 10:43:38,650] [threaten.py:275] [threaten:sear_info] [ERROR]- 解析威胁情报详细数据报错：'geo'
[2020-06-19 10:43:38,651] [threaten.py:275] [threaten:sear_info] [ERROR]- 解析威胁情报详细数据报错：'geo'
[2020-06-19 10:43:38,666] [basehttp.py:124] [basehttp:log_message] [INFO]- "GET /web/threaten/indexs?pIndex=0 HTTP/1.1" 200 13344
[2020-06-19 10:43:38,809] [threaten.py:275] [threaten:sear_info] [ERROR]- 解析威胁情报详细数据报错：'geo'
[2020-06-19 10:43:38,810] [threaten.py:275] [threaten:sear_info] [ERROR]- 解析威胁情报详细数据报错：'geo'
[2020-06-19 10:43:38,810] [threaten.py:275] [threaten:sear_info] [ERROR]- 解析威胁情报详细数据报错：'geo'
[2020-06-19 10:43:38,810] [threaten.py:275] [threaten:sear_info] [ERROR]- 解析威胁情报详细数据报错：'geo'
[2020-06-19 10:43:38,811] [threaten.py:275] [threaten:sear_info] [ERROR]- 解析威胁情报详细数据报错：'geo'
[2020-06-19 10:43:38,811] [basehttp.py:124] [basehttp:log_message] [INFO]- "GET /web/threaten/indexs?comid=0&page=1 HTTP/1.1" 200 1101
[2020-06-19 10:43:38,822] [basehttp.py:124] [basehttp:log_message] [INFO]- "GET /web/threaten/thattack HTTP/1.1" 200 564
[2020-06-19 10:43:38,841] [basehttp.py:124] [basehttp:log_message] [INFO]- "GET /web/threaten/thhit HTTP/1.1" 200 769
[2020-06-19 10:43:50,101] [basehttp.py:124] [basehttp:log_message] [INFO]- "GET /web/threaten/threat HTTP/1.1" 200 998
[2020-06-19 10:43:50,105] [basehttp.py:124] [basehttp:log_message] [INFO]- "GET /web/threaten/thactive HTTP/1.1" 200 280
[2020-06-19 10:43:50,107] [basehttp.py:124] [basehttp:log_message] [INFO]- "GET /web/Hit HTTP/1.1" 200 37
[2020-06-19 10:43:50,111] [basehttp.py:124] [basehttp:log_message] [INFO]- "GET /web/threaten/thnews HTTP/1.1" 200 1023
[2020-06-19 10:44:00,068] [threaten.py:275] [threaten:sear_info] [ERROR]- 解析威胁情报详细数据报错：'geo'
[2020-06-19 10:44:00,069] [threaten.py:275] [threaten:sear_info] [ERROR]- 解析威胁情报详细数据报错：'geo'
[2020-06-19 10:44:00,069] [threaten.py:275] [threaten:sear_info] [ERROR]- 解析威胁情报详细数据报错：'geo'
[2020-06-19 10:44:00,069] [threaten.py:275] [threaten:sear_info] [ERROR]- 解析威胁情报详细数据报错：'geo'
[2020-06-19 10:44:00,069] [threaten.py:275] [threaten:sear_info] [ERROR]- 解析威胁情报详细数据报错：'geo'
[2020-06-19 10:44:00,070] [threaten.py:275] [threaten:sear_info] [ERROR]- 解析威胁情报详细数据报错：'geo'
[2020-06-19 10:44:00,070] [threaten.py:275] [threaten:sear_info] [ERROR]- 解析威胁情报详细数据报错：'geo'
[2020-06-19 10:44:00,070] [threaten.py:275] [threaten:sear_info] [ERROR]- 解析威胁情报详细数据报错：'geo'
[2020-06-19 10:44:00,071] [basehttp.py:124] [basehttp:log_message] [INFO]- "GET /web/threaten/indexs?comid=0&page=2 HTTP/1.1" 200 1108
[2020-06-19 10:45:08,386] [threaten.py:274] [threaten:sear_info] [ERROR]- 解析威胁情报详细数据报错：'geo'
[2020-06-19 10:45:08,386] [threaten.py:274] [threaten:sear_info] [ERROR]- 解析威胁情报详细数据报错：'geo'
[2020-06-19 10:45:08,386] [threaten.py:274] [threaten:sear_info] [ERROR]- 解析威胁情报详细数据报错：'geo'
[2020-06-19 10:45:08,388] [threaten.py:274] [threaten:sear_info] [ERROR]- 解析威胁情报详细数据报错：'geo'
[2020-06-19 10:45:08,388] [threaten.py:274] [threaten:sear_info] [ERROR]- 解析威胁情报详细数据报错：'geo'
[2020-06-19 10:45:08,388] [threaten.py:274] [threaten:sear_info] [ERROR]- 解析威胁情报详细数据报错：'geo'
[2020-06-19 10:45:08,388] [threaten.py:274] [threaten:sear_info] [ERROR]- 解析威胁情报详细数据报错：'geo'
[2020-06-19 10:45:08,388] [threaten.py:274] [threaten:sear_info] [ERROR]- 解析威胁情报详细数据报错：'geo'
[2020-06-19 10:45:08,389] [basehttp.py:124] [basehttp:log_message] [INFO]- "GET /web/threaten/indexs?comid=0&page=6 HTTP/1.1" 200 340
[2020-06-19 10:51:56,507] [basehttp.py:124] [basehttp:log_message] [INFO]- "GET /web/threaten/indexs?comid=0&page=2 HTTP/1.1" 200 1140
[2020-06-19 10:51:56,524] [basehttp.py:124] [basehttp:log_message] [INFO]- "GET /web/threaten/indexs?comid=0&page=1 HTTP/1.1" 200 1083
[2020-06-19 10:51:56,538] [basehttp.py:124] [basehttp:log_message] [INFO]- "GET /web/threaten/indexs?comid=0&page=3 HTTP/1.1" 200 1258
[2020-06-19 10:51:58,803] [basehttp.py:124] [basehttp:log_message] [INFO]- "GET /web/threaten/indexs?comid=0&page=2 HTTP/1.1" 200 1140
[2020-06-19 10:52:01,017] [basehttp.py:124] [basehttp:log_message] [INFO]- "GET /web/threaten/indexs?comid=0&page=3 HTTP/1.1" 200 1096
[2020-06-19 10:52:04,146] [basehttp.py:124] [basehttp:log_message] [INFO]- "GET /web/threaten/indexs?comid=0&page=4 HTTP/1.1" 200 1173
[2020-06-19 10:52:06,060] [basehttp.py:124] [basehttp:log_message] [INFO]- "GET /web/threaten/indexs?comid=0&page=5 HTTP/1.1" 200 1272
[2020-06-19 10:53:57,427] [basehttp.py:124] [basehttp:log_message] [INFO]- "GET /web/center HTTP/1.1" 200 6867
[2020-06-19 10:54:00,441] [basehttp.py:124] [basehttp:log_message] [INFO]- "GET /web/index/5 HTTP/1.1" 200 17097
[2020-06-19 10:54:20,837] [basehttp.py:124] [basehttp:log_message] [INFO]- "GET /web/getnum?comid=5 HTTP/1.1" 200 212
[2020-06-19 10:54:20,845] [basehttp.py:124] [basehttp:log_message] [INFO]- "GET /web/visitport?comid=5 HTTP/1.1" 200 120
[2020-06-19 10:54:20,858] [basehttp.py:124] [basehttp:log_message] [INFO]- "GET /web/domain?comid=5 HTTP/1.1" 200 227
[2020-06-19 10:54:20,861] [basehttp.py:124] [basehttp:log_message] [INFO]- "GET /web/statuscode?comid=5 HTTP/1.1" 200 336
[2020-06-19 10:54:20,879] [basehttp.py:124] [basehttp:log_message] [INFO]- "GET /web/rqtraffic?comid=5 HTTP/1.1" 200 1241
[2020-06-19 10:54:20,910] [basehttp.py:124] [basehttp:log_message] [INFO]- "GET /web/rstraffic?comid=5 HTTP/1.1" 200 1172
[2020-06-19 10:54:21,484] [basehttp.py:124] [basehttp:log_message] [INFO]- "GET /web/Source_data?comid=5 HTTP/1.1" 200 467
[2020-06-19 10:54:21,871] [basehttp.py:124] [basehttp:log_message] [INFO]- "GET /web/fraction HTTP/1.1" 200 264
[2020-06-19 10:54:22,083] [basehttp.py:124] [basehttp:log_message] [INFO]- "GET /web/Hit?comid=5 HTTP/1.1" 200 33
[2020-06-19 10:54:22,933] [basehttp.py:124] [basehttp:log_message] [INFO]- "GET /web/trend?comid=5 HTTP/1.1" 200 780
[2020-06-19 10:54:31,271] [basehttp.py:124] [basehttp:log_message] [INFO]- "GET /web/attackmap?comid=5 HTTP/1.1" 200 285
[2020-06-19 10:55:12,997] [threaten.py:272] [threaten:sear_info] [ERROR]- 解析威胁情报详细数据报错：'geo'
[2020-06-19 10:55:12,997] [threaten.py:272] [threaten:sear_info] [ERROR]- 解析威胁情报详细数据报错：'geo'
[2020-06-19 10:55:12,997] [threaten.py:272] [threaten:sear_info] [ERROR]- 解析威胁情报详细数据报错：'geo'
[2020-06-19 10:55:12,998] [threaten.py:272] [threaten:sear_info] [ERROR]- 解析威胁情报详细数据报错：'geo'
[2020-06-19 10:55:13,004] [basehttp.py:124] [basehttp:log_message] [INFO]- "GET /web/threaten/indexs?pIndex=5 HTTP/1.1" 200 13277
[2020-06-19 10:55:13,135] [basehttp.py:124] [basehttp:log_message] [INFO]- "GET /web/threaten/thattack?comid=5 HTTP/1.1" 200 219
[2020-06-19 10:55:13,135] [basehttp.py:124] [basehttp:log_message] [INFO]- "GET /web/threaten/thhit?comid=5 HTTP/1.1" 200 490
[2020-06-19 10:55:13,139] [basehttp.py:124] [basehttp:log_message] [INFO]- "GET /web/threaten/thactive?comid=5 HTTP/1.1" 200 264
[2020-06-19 10:55:13,142] [basehttp.py:124] [basehttp:log_message] [INFO]- "GET /web/threaten/threat?comid=5 HTTP/1.1" 200 973
[2020-06-19 10:55:13,161] [basehttp.py:124] [basehttp:log_message] [INFO]- "GET /web/threaten/indexs?comid=5&page=1 HTTP/1.1" 200 1262
[2020-06-19 10:55:24,431] [basehttp.py:124] [basehttp:log_message] [INFO]- "GET /web/Hit?comid=5 HTTP/1.1" 200 33
[2020-06-19 10:55:24,475] [basehttp.py:124] [basehttp:log_message] [INFO]- "GET /web/threaten/thnews?comid=5 HTTP/1.1" 200 1011
[2020-06-19 10:56:51,332] [threaten.py:272] [threaten:sear_info] [ERROR]- 解析威胁情报详细数据报错：'geo'
[2020-06-19 10:56:51,332] [threaten.py:272] [threaten:sear_info] [ERROR]- 解析威胁情报详细数据报错：'geo'
[2020-06-19 10:56:51,333] [threaten.py:272] [threaten:sear_info] [ERROR]- 解析威胁情报详细数据报错：'geo'
[2020-06-19 10:56:51,333] [threaten.py:272] [threaten:sear_info] [ERROR]- 解析威胁情报详细数据报错：'geo'
[2020-06-19 10:56:51,333] [threaten.py:272] [threaten:sear_info] [ERROR]- 解析威胁情报详细数据报错：'geo'
[2020-06-19 10:56:51,333] [threaten.py:272] [threaten:sear_info] [ERROR]- 解析威胁情报详细数据报错：'geo'
[2020-06-19 10:56:51,337] [basehttp.py:124] [basehttp:log_message] [INFO]- "GET /web/threaten/indexs?pIndex=5 HTTP/1.1" 200 13277
[2020-06-19 10:56:51,408] [basehttp.py:124] [basehttp:log_message] [INFO]- "GET /web/threaten/thattack?comid=5 HTTP/1.1" 200 219
[2020-06-19 10:56:51,421] [basehttp.py:124] [basehttp:log_message] [INFO]- "GET /web/threaten/thhit?comid=5 HTTP/1.1" 200 490
[2020-06-19 10:56:51,427] [basehttp.py:124] [basehttp:log_message] [INFO]- "GET /web/threaten/thactive?comid=5 HTTP/1.1" 200 264
[2020-06-19 10:56:51,427] [basehttp.py:124] [basehttp:log_message] [INFO]- "GET /web/threaten/threat?comid=5 HTTP/1.1" 200 973
[2020-06-19 10:56:51,445] [basehttp.py:124] [basehttp:log_message] [INFO]- "GET /web/Hit?comid=5 HTTP/1.1" 200 33
[2020-06-19 10:56:51,461] [basehttp.py:124] [basehttp:log_message] [INFO]- "GET /web/threaten/indexs?comid=5&page=1 HTTP/1.1" 200 1262
[2020-06-19 10:56:51,462] [basehttp.py:124] [basehttp:log_message] [INFO]- "GET /web/threaten/thnews?comid=5 HTTP/1.1" 200 1011
[2020-06-19 10:57:46,853] [basehttp.py:124] [basehttp:log_message] [INFO]- "GET /web/threaten/indexs?comid=5&page=2 HTTP/1.1" 200 1363
[2020-06-19 10:57:48,370] [basehttp.py:124] [basehttp:log_message] [INFO]- "GET /web/threaten/indexs?comid=5&page=3 HTTP/1.1" 200 1419
[2020-06-19 10:57:49,594] [basehttp.py:124] [basehttp:log_message] [INFO]- "GET /web/threaten/indexs?comid=5&page=4 HTTP/1.1" 200 1420
[2020-06-19 10:57:50,910] [basehttp.py:124] [basehttp:log_message] [INFO]- "GET /web/threaten/indexs?comid=5&page=5 HTTP/1.1" 200 1420
[2020-06-19 10:57:51,517] [basehttp.py:124] [basehttp:log_message] [INFO]- "GET /web/threaten/indexs?comid=5&page=6 HTTP/1.1" 200 1421
[2020-06-19 11:03:12,531] [basehttp.py:124] [basehttp:log_message] [INFO]- "GET /web/threaten/indexs?comid=5&page=2 HTTP/1.1" 200 1363
[2020-06-19 11:04:50,049] [basehttp.py:124] [basehttp:log_message] [INFO]- "GET /web/center HTTP/1.1" 200 6867
[2020-06-19 11:04:50,077] [basehttp.py:124] [basehttp:log_message] [INFO]- "GET /static/monweb/css/bootstrap.min.css.map HTTP/1.1" 200 542194
[2020-06-19 11:04:52,600] [basehttp.py:124] [basehttp:log_message] [INFO]- "GET /web/index/0 HTTP/1.1" 200 16441
[2020-06-19 11:04:52,612] [basehttp.py:124] [basehttp:log_message] [INFO]- "GET /static/monit/css/comon0.css HTTP/1.1" 304 0
[2020-06-19 11:05:15,349] [basehttp.py:124] [basehttp:log_message] [INFO]- "GET /web/visitport HTTP/1.1" 200 234
[2020-06-19 11:05:15,391] [basehttp.py:124] [basehttp:log_message] [INFO]- "GET /web/getnum HTTP/1.1" 200 296
[2020-06-19 11:05:15,455] [basehttp.py:124] [basehttp:log_message] [INFO]- "GET /web/domain HTTP/1.1" 200 1377
[2020-06-19 11:05:15,472] [basehttp.py:124] [basehttp:log_message] [INFO]- "GET /web/trend HTTP/1.1" 200 856
[2020-06-19 11:05:15,541] [basehttp.py:124] [basehttp:log_message] [INFO]- "GET /web/Hit HTTP/1.1" 200 37
[2020-06-19 11:05:15,555] [basehttp.py:124] [basehttp:log_message] [INFO]- "GET /web/statuscode HTTP/1.1" 200 5630
[2020-06-19 11:05:15,570] [basehttp.py:124] [basehttp:log_message] [INFO]- "GET /web/rqtraffic HTTP/1.1" 200 2411
[2020-06-19 11:05:15,646] [basehttp.py:124] [basehttp:log_message] [INFO]- "GET /web/rstraffic HTTP/1.1" 200 2469
[2020-06-19 11:05:15,964] [basehttp.py:124] [basehttp:log_message] [INFO]- "GET /web/fraction HTTP/1.1" 200 261
[2020-06-19 11:05:23,510] [basehttp.py:124] [basehttp:log_message] [INFO]- "GET /web/Source_data HTTP/1.1" 200 590
[2020-06-19 11:05:24,454] [basehttp.py:124] [basehttp:log_message] [INFO]- "GET /web/attackmap HTTP/1.1" 200 4826
[2020-06-19 11:06:13,268] [exception.py:135] [exception:handle_uncaught_exception] [ERROR]- Internal Server Error: /web/threaten/indexs
Traceback (most recent call last):
  File "E:\project_env\lib\site-packages\django\core\handlers\exception.py", line 41, in inner
    response = get_response(request)
  File "E:\project_env\lib\site-packages\django\core\handlers\base.py", line 187, in _get_response
    response = self.process_exception_by_middleware(e, request)
  File "E:\project_env\lib\site-packages\django\core\handlers\base.py", line 185, in _get_response
    response = wrapped_callback(request, *callback_args, **callback_kwargs)
  File "E:\project_env\lib\site-packages\django\views\generic\base.py", line 68, in view
    return self.dispatch(request, *args, **kwargs)
  File "E:\project_env\lib\site-packages\django\views\generic\base.py", line 88, in dispatch
    return handler(request, *args, **kwargs)
  File "E:\monitor\HqMonitor\web\views\threaten.py", line 31, in get
    result =self.seardat(comid)
  File "E:\monitor\HqMonitor\web\views\threaten.py", line 83, in seardat
    if int(comid) == 0:  # 是否携带用户信息
TypeError: int() argument must be a string, a bytes-like object or a number, not 'NoneType'
[2020-06-19 11:06:13,370] [basehttp.py:124] [basehttp:log_message] [ERROR]- "GET /web/threaten/indexs?comid=0 HTTP/1.1" 500 84085
[2020-06-19 11:07:18,683] [threaten.py:267] [threaten:sear_info] [ERROR]- 解析威胁情报详细数据报错：'geo'
[2020-06-19 11:07:18,683] [threaten.py:267] [threaten:sear_info] [ERROR]- 解析威胁情报详细数据报错：'geo'
[2020-06-19 11:07:18,683] [threaten.py:267] [threaten:sear_info] [ERROR]- 解析威胁情报详细数据报错：'geo'
[2020-06-19 11:07:18,683] [threaten.py:267] [threaten:sear_info] [ERROR]- 解析威胁情报详细数据报错：'geo'
[2020-06-19 11:07:18,698] [basehttp.py:124] [basehttp:log_message] [INFO]- "GET /web/threaten/indexs?comid=0 HTTP/1.1" 200 13228
[2020-06-19 11:07:18,717] [basehttp.py:124] [basehttp:log_message] [INFO]- "GET /static/monit/css/layui.css HTTP/1.1" 304 0
[2020-06-19 11:07:18,834] [threaten.py:267] [threaten:sear_info] [ERROR]- 解析威胁情报详细数据报错：'geo'
[2020-06-19 11:07:18,834] [threaten.py:267] [threaten:sear_info] [ERROR]- 解析威胁情报详细数据报错：'geo'
[2020-06-19 11:07:18,834] [threaten.py:267] [threaten:sear_info] [ERROR]- 解析威胁情报详细数据报错：'geo'
[2020-06-19 11:07:18,835] [threaten.py:267] [threaten:sear_info] [ERROR]- 解析威胁情报详细数据报错：'geo'
[2020-06-19 11:07:18,835] [basehttp.py:124] [basehttp:log_message] [INFO]- "GET /web/threaten/indexs?comid=0&page=1 HTTP/1.1" 200 1166
[2020-06-19 11:07:18,857] [basehttp.py:124] [basehttp:log_message] [INFO]- "GET /web/threaten/thattack HTTP/1.1" 200 564
[2020-06-19 11:07:19,863] [basehttp.py:124] [basehttp:log_message] [INFO]- "GET /web/threaten/thhit HTTP/1.1" 200 769
[2020-06-19 11:07:19,869] [basehttp.py:124] [basehttp:log_message] [INFO]- "GET /web/threaten/thactive HTTP/1.1" 200 279
[2020-06-19 11:07:21,116] [basehttp.py:124] [basehttp:log_message] [INFO]- "GET /web/threaten/thnews HTTP/1.1" 200 1021
[2020-06-19 11:07:21,124] [basehttp.py:124] [basehttp:log_message] [INFO]- "GET /web/threaten/threat HTTP/1.1" 200 996
[2020-06-19 11:07:21,132] [basehttp.py:124] [basehttp:log_message] [INFO]- "GET /web/Hit HTTP/1.1" 200 37
[2020-06-19 11:08:25,979] [threaten.py:267] [threaten:sear_info] [ERROR]- 解析威胁情报详细数据报错：'geo'
[2020-06-19 11:08:25,979] [threaten.py:267] [threaten:sear_info] [ERROR]- 解析威胁情报详细数据报错：'geo'
[2020-06-19 11:08:25,979] [threaten.py:267] [threaten:sear_info] [ERROR]- 解析威胁情报详细数据报错：'geo'
[2020-06-19 11:08:25,983] [basehttp.py:124] [basehttp:log_message] [INFO]- "GET /web/threaten/indexs?comid=0 HTTP/1.1" 200 13228
[2020-06-19 11:08:26,110] [basehttp.py:124] [basehttp:log_message] [INFO]- "GET /web/threaten/thhit HTTP/1.1" 200 769
[2020-06-19 11:08:26,111] [basehttp.py:124] [basehttp:log_message] [INFO]- "GET /web/threaten/thactive HTTP/1.1" 200 279
[2020-06-19 11:08:26,113] [basehttp.py:124] [basehttp:log_message] [INFO]- "GET /web/threaten/threat HTTP/1.1" 200 996
[2020-06-19 11:08:26,119] [threaten.py:267] [threaten:sear_info] [ERROR]- 解析威胁情报详细数据报错：'geo'
[2020-06-19 11:08:26,120] [threaten.py:267] [threaten:sear_info] [ERROR]- 解析威胁情报详细数据报错：'geo'
[2020-06-19 11:08:26,120] [threaten.py:267] [threaten:sear_info] [ERROR]- 解析威胁情报详细数据报错：'geo'
[2020-06-19 11:08:26,121] [basehttp.py:124] [basehttp:log_message] [INFO]- "GET /web/threaten/indexs?comid=0&page=1 HTTP/1.1" 200 1118
[2020-06-19 11:08:26,284] [basehttp.py:124] [basehttp:log_message] [INFO]- "GET /web/threaten/thattack HTTP/1.1" 200 564
[2020-06-19 11:08:37,377] [basehttp.py:124] [basehttp:log_message] [INFO]- "GET /web/Hit HTTP/1.1" 200 37
[2020-06-19 11:08:37,440] [basehttp.py:124] [basehttp:log_message] [INFO]- "GET /web/threaten/thnews HTTP/1.1" 200 1021
[2020-06-19 11:09:18,036] [basehttp.py:124] [basehttp:log_message] [INFO]- "GET /web/threaten/indexs?comid=0 HTTP/1.1" 200 13465
[2020-06-19 11:09:18,104] [basehttp.py:124] [basehttp:log_message] [INFO]- "GET /web/threaten/thattack HTTP/1.1" 200 564
[2020-06-19 11:09:18,118] [basehttp.py:124] [basehttp:log_message] [INFO]- "GET /web/threaten/indexs?comid=0&page=1 HTTP/1.1" 200 1136
[2020-06-19 11:09:18,118] [basehttp.py:124] [basehttp:log_message] [INFO]- "GET /web/threaten/thhit HTTP/1.1" 200 769
[2020-06-19 11:09:18,123] [basehttp.py:124] [basehttp:log_message] [INFO]- "GET /web/Hit HTTP/1.1" 200 37
[2020-06-19 11:09:18,124] [basehttp.py:124] [basehttp:log_message] [INFO]- "GET /web/threaten/thactive HTTP/1.1" 200 279
[2020-06-19 11:09:18,134] [basehttp.py:124] [basehttp:log_message] [INFO]- "GET /web/threaten/threat HTTP/1.1" 200 996
[2020-06-19 11:09:18,165] [basehttp.py:124] [basehttp:log_message] [INFO]- "GET /web/threaten/thnews HTTP/1.1" 200 1021
[2020-06-19 11:09:30,489] [basehttp.py:124] [basehttp:log_message] [INFO]- "GET / HTTP/1.1" 200 5942
[2020-06-19 11:09:30,559] [basehttp.py:124] [basehttp:log_message] [INFO]- "GET /verify HTTP/1.1" 200 1552
[2020-06-19 11:09:30,572] [base.py:152] [base:get_response] [WARNING]- Not Found: /favicon.ico
[2020-06-19 11:09:30,573] [basehttp.py:124] [basehttp:log_message] [WARNING]- "GET /favicon.ico HTTP/1.1" 404 6801
[2020-06-19 11:09:44,381] [basehttp.py:124] [basehttp:log_message] [INFO]- "POST /dologin HTTP/1.1" 302 0
[2020-06-19 11:09:44,416] [basehttp.py:124] [basehttp:log_message] [INFO]- "GET /web/center HTTP/1.1" 200 6874
[2020-06-19 11:09:46,535] [basehttp.py:124] [basehttp:log_message] [INFO]- "GET /web/index/5 HTTP/1.1" 200 17096
[2020-06-19 11:09:46,549] [basehttp.py:124] [basehttp:log_message] [INFO]- "GET /static/monit/css/comon0.css HTTP/1.1" 304 0
[2020-06-19 11:09:46,549] [basehttp.py:124] [basehttp:log_message] [INFO]- "GET /static/monit/js/js.js HTTP/1.1" 304 0
[2020-06-19 11:09:46,649] [basehttp.py:124] [basehttp:log_message] [INFO]- "GET /web/getnum?comid=5 HTTP/1.1" 200 226
[2020-06-19 11:09:46,652] [basehttp.py:124] [basehttp:log_message] [INFO]- "GET /web/statuscode?comid=5 HTTP/1.1" 200 608
[2020-06-19 11:09:46,663] [basehttp.py:124] [basehttp:log_message] [INFO]- "GET /web/domain?comid=5 HTTP/1.1" 200 241
[2020-06-19 11:09:46,672] [basehttp.py:124] [basehttp:log_message] [INFO]- "GET /web/visitport?comid=5 HTTP/1.1" 200 121
[2020-06-19 11:09:46,704] [basehttp.py:124] [basehttp:log_message] [INFO]- "GET /web/trend?comid=5 HTTP/1.1" 200 795
[2020-06-19 11:09:46,721] [basehttp.py:124] [basehttp:log_message] [INFO]- "GET /web/rqtraffic?comid=5 HTTP/1.1" 200 1389
[2020-06-19 11:09:46,735] [basehttp.py:124] [basehttp:log_message] [INFO]- "GET /web/Hit?comid=5 HTTP/1.1" 200 33
[2020-06-19 11:09:46,819] [basehttp.py:124] [basehttp:log_message] [INFO]- "GET /web/Source_data?comid=5 HTTP/1.1" 200 467
[2020-06-19 11:09:47,055] [basehttp.py:124] [basehttp:log_message] [INFO]- "GET /web/fraction HTTP/1.1" 200 263
[2020-06-19 11:09:47,251] [basehttp.py:124] [basehttp:log_message] [INFO]- "GET /web/rstraffic?comid=5 HTTP/1.1" 200 1190
[2020-06-19 11:09:55,852] [basehttp.py:124] [basehttp:log_message] [INFO]- "GET /web/attackmap?comid=5 HTTP/1.1" 200 567
[2020-06-19 11:10:02,828] [basehttp.py:124] [basehttp:log_message] [INFO]- "GET /web/threaten/indexs?comid=5 HTTP/1.1" 200 13513
[2020-06-19 11:10:02,842] [basehttp.py:124] [basehttp:log_message] [INFO]- "GET /static/monit/css/layui.css HTTP/1.1" 304 0
[2020-06-19 11:10:02,842] [basehttp.py:124] [basehttp:log_message] [INFO]- "GET /static/monit/js/threaten.js HTTP/1.1" 304 0
[2020-06-19 11:10:02,908] [basehttp.py:124] [basehttp:log_message] [INFO]- "GET /web/threaten/thattack?comid=5 HTTP/1.1" 200 219
[2020-06-19 11:10:02,908] [basehttp.py:124] [basehttp:log_message] [INFO]- "GET /web/threaten/thhit?comid=5 HTTP/1.1" 200 490
[2020-06-19 11:10:02,922] [basehttp.py:124] [basehttp:log_message] [INFO]- "GET /web/threaten/threat?comid=5 HTTP/1.1" 200 973
[2020-06-19 11:10:02,923] [basehttp.py:124] [basehttp:log_message] [INFO]- "GET /web/Hit?comid=5 HTTP/1.1" 200 33
[2020-06-19 11:10:02,924] [basehttp.py:124] [basehttp:log_message] [INFO]- "GET /web/threaten/thactive?comid=5 HTTP/1.1" 200 264
[2020-06-19 11:10:02,932] [basehttp.py:124] [basehttp:log_message] [INFO]- "GET /web/threaten/indexs?comid=5&page=1 HTTP/1.1" 200 1262
[2020-06-19 11:10:02,937] [basehttp.py:124] [basehttp:log_message] [INFO]- "GET /web/threaten/thnews?comid=5 HTTP/1.1" 200 1011
[2020-06-19 11:10:24,301] [basehttp.py:124] [basehttp:log_message] [INFO]- "GET /web/threaten/indexs?comid=5 HTTP/1.1" 200 13513
[2020-06-19 11:10:24,377] [basehttp.py:124] [basehttp:log_message] [INFO]- "GET /web/threaten/thattack?comid=5 HTTP/1.1" 200 219
[2020-06-19 11:10:24,377] [basehttp.py:124] [basehttp:log_message] [INFO]- "GET /web/threaten/thhit?comid=5 HTTP/1.1" 200 490
[2020-06-19 11:10:24,393] [basehttp.py:124] [basehttp:log_message] [INFO]- "GET /web/threaten/threat?comid=5 HTTP/1.1" 200 973
[2020-06-19 11:10:24,394] [basehttp.py:124] [basehttp:log_message] [INFO]- "GET /web/Hit?comid=5 HTTP/1.1" 200 33
[2020-06-19 11:10:24,395] [basehttp.py:124] [basehttp:log_message] [INFO]- "GET /web/threaten/thactive?comid=5 HTTP/1.1" 200 264
[2020-06-19 11:10:24,398] [basehttp.py:124] [basehttp:log_message] [INFO]- "GET /web/threaten/indexs?comid=5&page=1 HTTP/1.1" 200 1262
[2020-06-19 11:10:24,420] [basehttp.py:124] [basehttp:log_message] [INFO]- "GET /web/threaten/thnews?comid=5 HTTP/1.1" 200 1011
[2020-06-19 11:11:11,822] [basehttp.py:124] [basehttp:log_message] [INFO]- "GET /web/threaten/indexs?comid=5&page=5 HTTP/1.1" 200 1420
[2020-06-19 11:11:22,668] [basehttp.py:124] [basehttp:log_message] [INFO]- "GET /web/threaten/indexs?comid=5&page=1 HTTP/1.1" 200 1262
[2020-06-19 11:11:26,882] [basehttp.py:124] [basehttp:log_message] [INFO]- "GET /web/threaten/indexs?comid=5&page=7 HTTP/1.1" 200 408
[2020-06-19 11:11:28,918] [basehttp.py:124] [basehttp:log_message] [INFO]- "GET /web/threaten/indexs?comid=5&page=5 HTTP/1.1" 200 1420
[2020-06-19 11:11:30,574] [basehttp.py:124] [basehttp:log_message] [INFO]- "GET /web/threaten/indexs?comid=5&page=4 HTTP/1.1" 200 1420
[2020-06-19 11:11:32,847] [basehttp.py:124] [basehttp:log_message] [INFO]- "GET /web/threaten/indexs?comid=5&page=3 HTTP/1.1" 200 1419
[2020-06-19 11:11:34,868] [basehttp.py:124] [basehttp:log_message] [INFO]- "GET /web/threaten/indexs?comid=5&page=2 HTTP/1.1" 200 1363
