[2020-06-18 16:57:28,346] [threaten.py:151] [threaten:seardat] [ERROR]- 请求出错：Compinfo matching query does not exist.
[2020-06-18 16:58:31,065] [threaten.py:152] [threaten:seardat] [ERROR]- 请求出错：Compinfo matching query does not exist.
[2020-06-18 16:59:20,604] [threaten.py:152] [threaten:seardat] [ERROR]- 请求出错：Compinfo matching query does not exist.
[2020-06-18 17:27:16,580] [threaten.py:152] [threaten:seardat] [ERROR]- 请求出错：Compinfo matching query does not exist.
[2020-06-18 17:27:17,887] [threaten.py:152] [threaten:seardat] [ERROR]- 请求出错：Compinfo matching query does not exist.
[2020-06-18 17:27:42,318] [threaten.py:152] [threaten:seardat] [ERROR]- 请求出错：Compinfo matching query does not exist.
[2020-06-18 17:28:23,869] [threaten.py:152] [threaten:seardat] [ERROR]- 请求出错：Compinfo matching query does not exist.
[2020-06-18 17:29:41,217] [threaten.py:152] [threaten:seardat] [ERROR]- 请求出错：Compinfo matching query does not exist.
[2020-06-18 17:29:42,458] [threaten.py:152] [threaten:seardat] [ERROR]- 请求出错：Compinfo matching query does not exist.
[2020-06-18 17:31:43,108] [threaten.py:313] [threaten:sear_info] [ERROR]- 获取数据出错：list index out of range
[2020-06-18 17:31:45,664] [threaten.py:313] [threaten:sear_info] [ERROR]- 获取数据出错：list index out of range
[2020-06-18 17:32:24,112] [threaten.py:314] [threaten:sear_info] [ERROR]- 获取数据出错：list index out of range
[2020-06-18 17:32:25,488] [threaten.py:314] [threaten:sear_info] [ERROR]- 获取数据出错：list index out of range
[2020-06-18 17:33:25,358] [threaten.py:315] [threaten:sear_info] [ERROR]- 获取数据出错：list index out of range
[2020-06-18 17:33:27,138] [threaten.py:315] [threaten:sear_info] [ERROR]- 获取数据出错：list index out of range
[2020-06-18 17:35:55,086] [threaten.py:316] [threaten:sear_info] [ERROR]- 威胁情报-数据-获取数据出错：list index out of range
[2020-06-18 17:35:56,685] [threaten.py:316] [threaten:sear_info] [ERROR]- 威胁情报-数据-获取数据出错：list index out of range
[2020-06-18 17:36:38,590] [threaten.py:315] [threaten:sear_info] [ERROR]- 威胁情报-数据-获取数据出错：list index out of range
[2020-06-18 17:37:37,864] [threaten.py:316] [threaten:sear_info] [ERROR]- 威胁情报-数据-获取数据出错：list index out of range
[2020-06-18 17:37:40,291] [threaten.py:316] [threaten:sear_info] [ERROR]- 威胁情报-数据-获取数据出错：list index out of range
[2020-06-18 17:38:51,591] [threaten.py:316] [threaten:sear_info] [ERROR]- 威胁情报-数据-获取数据出错：list index out of range
[2020-06-18 17:38:54,140] [threaten.py:316] [threaten:sear_info] [ERROR]- 威胁情报-数据-获取数据出错：list index out of range
[2020-06-18 17:40:03,644] [threaten.py:316] [threaten:sear_info] [ERROR]- 威胁情报-数据-获取数据出错：list index out of range
[2020-06-18 17:40:04,948] [threaten.py:316] [threaten:sear_info] [ERROR]- 威胁情报-数据-获取数据出错：list index out of range
[2020-06-18 17:41:22,085] [threaten.py:318] [threaten:sear_info] [ERROR]- 威胁情报-数据-获取数据出错：list index out of range
[2020-06-18 17:41:23,464] [threaten.py:318] [threaten:sear_info] [ERROR]- 威胁情报-数据-获取数据出错：list index out of range
[2020-06-18 17:42:18,668] [threaten.py:318] [threaten:sear_info] [ERROR]- 威胁情报-数据-获取数据出错：list index out of range
[2020-06-18 17:42:21,345] [threaten.py:318] [threaten:sear_info] [ERROR]- 威胁情报-数据-获取数据出错：list index out of range
[2020-06-18 17:44:06,014] [threaten.py:318] [threaten:sear_info] [ERROR]- 威胁情报-数据-获取数据出错：'geo'
[2020-06-18 17:44:09,359] [threaten.py:318] [threaten:sear_info] [ERROR]- 威胁情报-数据-获取数据出错：'geo'
[2020-06-18 17:46:18,090] [threaten.py:318] [threaten:sear_info] [ERROR]- 威胁情报-数据-获取数据出错：'geo'
[2020-06-18 17:47:15,601] [threaten.py:318] [threaten:sear_info] [ERROR]- 威胁情报-数据-获取数据出错：'geo'
[2020-06-18 17:47:28,455] [threaten.py:318] [threaten:sear_info] [ERROR]- 威胁情报-数据-获取数据出错：'geo'
[2020-06-18 17:48:18,128] [threaten.py:319] [threaten:sear_info] [ERROR]- 威胁情报-数据-获取数据出错：'geo'
[2020-06-18 17:48:19,980] [threaten.py:319] [threaten:sear_info] [ERROR]- 威胁情报-数据-获取数据出错：'geo'
[2020-06-18 17:51:05,072] [threaten.py:317] [threaten:sear_info] [ERROR]- 威胁情报-数据-获取数据出错：'geo'
[2020-06-18 17:51:06,586] [threaten.py:317] [threaten:sear_info] [ERROR]- 威胁情报-数据-获取数据出错：'geo'
[2020-06-18 17:55:51,611] [threaten.py:326] [threaten:sear_info] [ERROR]- 威胁情报-数据-获取数据出错：'geo'
[2020-06-18 17:59:52,106] [threaten.py:329] [threaten:sear_info] [ERROR]- 威胁情报-数据-获取数据出错：'geo'
[2020-06-18 18:05:58,137] [threaten.py:329] [threaten:sear_info] [ERROR]- 威胁情报-数据-获取数据出错：'geo'
